[Wed Dec 31 10:03:42.106853 2014] [:error] [pid 709:tid 140202179892992] [remote 192.168.15.203:19043] mod_wsgi (pid=709): Target WSGI script '/var/www/testsite/testsite/wsgi.py' cannot be loaded as Python module.
[Wed Dec 31 10:03:42.107127 2014] [:error] [pid 709:tid 140202179892992] [remote 192.168.15.203:19043] mod_wsgi (pid=709): Exception occurred processing WSGI script '/var/www/testsite/testsite/wsgi.py'.
[Wed Dec 31 10:03:42.107173 2014] [:error] [pid 709:tid 140202179892992] [remote 192.168.15.203:19043] Traceback (most recent call last):
[Wed Dec 31 10:03:42.107198 2014] [:error] [pid 709:tid 140202179892992] [remote 192.168.15.203:19043]   File "/var/www/testsite/testsite/wsgi.py", line 16, in <module>
[Wed Dec 31 10:03:42.107259 2014] [:error] [pid 709:tid 140202179892992] [remote 192.168.15.203:19043]     application = get_wsgi_application()
[Wed Dec 31 10:03:42.107271 2014] [:error] [pid 709:tid 140202179892992] [remote 192.168.15.203:19043]   File "/usr/local/lib/python2.7/dist-packages/django/core/wsgi.py", line 14, in get_wsgi_application
[Wed Dec 31 10:03:42.119485 2014] [:error] [pid 709:tid 140202179892992] [remote 192.168.15.203:19043]     django.setup()
[Wed Dec 31 10:03:42.119503 2014] [:error] [pid 709:tid 140202179892992] [remote 192.168.15.203:19043]   File "/usr/local/lib/python2.7/dist-packages/django/__init__.py", line 21, in setup
[Wed Dec 31 10:03:42.128745 2014] [:error] [pid 709:tid 140202179892992] [remote 192.168.15.203:19043]     apps.populate(settings.INSTALLED_APPS)
[Wed Dec 31 10:03:42.128765 2014] [:error] [pid 709:tid 140202179892992] [remote 192.168.15.203:19043]   File "/usr/local/lib/python2.7/dist-packages/django/apps/registry.py", line 115, in populate
[Wed Dec 31 10:03:42.132695 2014] [:error] [pid 709:tid 140202179892992] [remote 192.168.15.203:19043]     app_config.ready()
[Wed Dec 31 10:03:42.132713 2014] [:error] [pid 709:tid 140202179892992] [remote 192.168.15.203:19043]   File "/usr/local/lib/python2.7/dist-packages/django/contrib/admin/apps.py", line 22, in ready
[Wed Dec 31 10:03:42.141812 2014] [:error] [pid 709:tid 140202179892992] [remote 192.168.15.203:19043]     self.module.autodiscover()
[Wed Dec 31 10:03:42.141827 2014] [:error] [pid 709:tid 140202179892992] [remote 192.168.15.203:19043]   File "/usr/local/lib/python2.7/dist-packages/django/contrib/admin/__init__.py", line 23, in autodiscover
[Wed Dec 31 10:03:42.147903 2014] [:error] [pid 709:tid 140202179892992] [remote 192.168.15.203:19043]     autodiscover_modules('admin', register_to=site)
[Wed Dec 31 10:03:42.147918 2014] [:error] [pid 709:tid 140202179892992] [remote 192.168.15.203:19043]   File "/usr/local/lib/python2.7/dist-packages/django/utils/module_loading.py", line 74, in autodiscover_modules
[Wed Dec 31 10:03:42.153990 2014] [:error] [pid 709:tid 140202179892992] [remote 192.168.15.203:19043]     import_module('%s.%s' % (app_config.name, module_to_search))
[Wed Dec 31 10:03:42.154005 2014] [:error] [pid 709:tid 140202179892992] [remote 192.168.15.203:19043]   File "/usr/lib/python2.7/importlib/__init__.py", line 37, in import_module
[Wed Dec 31 10:03:42.164577 2014] [:error] [pid 709:tid 140202179892992] [remote 192.168.15.203:19043]     __import__(name)
[Wed Dec 31 10:03:42.164619 2014] [:error] [pid 709:tid 140202179892992] [remote 192.168.15.203:19043]   File "/var/www/testsite/polls/admin.py", line 2, in <module>
[Wed Dec 31 10:03:42.164680 2014] [:error] [pid 709:tid 140202179892992] [remote 192.168.15.203:19043]     from testsite.polls.models import Choice, Question
[Wed Dec 31 10:03:42.164706 2014] [:error] [pid 709:tid 140202179892992] [remote 192.168.15.203:19043] ImportError: No module named polls.models
[Wed Dec 31 10:03:45.597782 2014] [:error] [pid 710:tid 140202179892992] [remote 192.168.15.203:19043] mod_wsgi (pid=710): Target WSGI script '/var/www/testsite/testsite/wsgi.py' cannot be loaded as Python module.
[Wed Dec 31 10:03:45.598012 2014] [:error] [pid 710:tid 140202179892992] [remote 192.168.15.203:19043] mod_wsgi (pid=710): Exception occurred processing WSGI script '/var/www/testsite/testsite/wsgi.py'.
[Wed Dec 31 10:03:45.598094 2014] [:error] [pid 710:tid 140202179892992] [remote 192.168.15.203:19043] Traceback (most recent call last):
[Wed Dec 31 10:03:45.598135 2014] [:error] [pid 710:tid 140202179892992] [remote 192.168.15.203:19043]   File "/var/www/testsite/testsite/wsgi.py", line 16, in <module>
[Wed Dec 31 10:03:45.598220 2014] [:error] [pid 710:tid 140202179892992] [remote 192.168.15.203:19043]     application = get_wsgi_application()
[Wed Dec 31 10:03:45.598246 2014] [:error] [pid 710:tid 140202179892992] [remote 192.168.15.203:19043]   File "/usr/local/lib/python2.7/dist-packages/django/core/wsgi.py", line 14, in get_wsgi_application
[Wed Dec 31 10:03:45.598305 2014] [:error] [pid 710:tid 140202179892992] [remote 192.168.15.203:19043]     django.setup()
[Wed Dec 31 10:03:45.598330 2014] [:error] [pid 710:tid 140202179892992] [remote 192.168.15.203:19043]   File "/usr/local/lib/python2.7/dist-packages/django/__init__.py", line 21, in setup
[Wed Dec 31 10:03:45.598386 2014] [:error] [pid 710:tid 140202179892992] [remote 192.168.15.203:19043]     apps.populate(settings.INSTALLED_APPS)
[Wed Dec 31 10:03:45.598410 2014] [:error] [pid 710:tid 140202179892992] [remote 192.168.15.203:19043]   File "/usr/local/lib/python2.7/dist-packages/django/apps/registry.py", line 115, in populate
[Wed Dec 31 10:03:45.598706 2014] [:error] [pid 710:tid 140202179892992] [remote 192.168.15.203:19043]     app_config.ready()
[Wed Dec 31 10:03:45.598732 2014] [:error] [pid 710:tid 140202179892992] [remote 192.168.15.203:19043]   File "/usr/local/lib/python2.7/dist-packages/django/contrib/admin/apps.py", line 22, in ready
[Wed Dec 31 10:03:45.598819 2014] [:error] [pid 710:tid 140202179892992] [remote 192.168.15.203:19043]     self.module.autodiscover()
[Wed Dec 31 10:03:45.598841 2014] [:error] [pid 710:tid 140202179892992] [remote 192.168.15.203:19043]   File "/usr/local/lib/python2.7/dist-packages/django/contrib/admin/__init__.py", line 23, in autodiscover
[Wed Dec 31 10:03:45.598924 2014] [:error] [pid 710:tid 140202179892992] [remote 192.168.15.203:19043]     autodiscover_modules('admin', register_to=site)
[Wed Dec 31 10:03:45.598945 2014] [:error] [pid 710:tid 140202179892992] [remote 192.168.15.203:19043]   File "/usr/local/lib/python2.7/dist-packages/django/utils/module_loading.py", line 74, in autodiscover_modules
[Wed Dec 31 10:03:45.599150 2014] [:error] [pid 710:tid 140202179892992] [remote 192.168.15.203:19043]     import_module('%s.%s' % (app_config.name, module_to_search))
[Wed Dec 31 10:03:45.599173 2014] [:error] [pid 710:tid 140202179892992] [remote 192.168.15.203:19043]   File "/usr/lib/python2.7/importlib/__init__.py", line 37, in import_module
[Wed Dec 31 10:03:45.599256 2014] [:error] [pid 710:tid 140202179892992] [remote 192.168.15.203:19043]     __import__(name)
[Wed Dec 31 10:03:45.599276 2014] [:error] [pid 710:tid 140202179892992] [remote 192.168.15.203:19043]   File "/var/www/testsite/polls/admin.py", line 2, in <module>
[Wed Dec 31 10:03:45.599324 2014] [:error] [pid 710:tid 140202179892992] [remote 192.168.15.203:19043]     from testsite.polls.models import Choice, Question
[Wed Dec 31 10:03:45.599357 2014] [:error] [pid 710:tid 140202179892992] [remote 192.168.15.203:19043] ImportError: No module named polls.models
[Wed Dec 31 10:05:11.295492 2014] [:error] [pid 709:tid 140202062395136] [remote 192.168.15.203:12387] mod_wsgi (pid=709): Target WSGI script '/var/www/testsite/testsite/wsgi.py' cannot be loaded as Python module.
[Wed Dec 31 10:05:11.295598 2014] [:error] [pid 709:tid 140202062395136] [remote 192.168.15.203:12387] mod_wsgi (pid=709): Exception occurred processing WSGI script '/var/www/testsite/testsite/wsgi.py'.
[Wed Dec 31 10:05:11.295652 2014] [:error] [pid 709:tid 140202062395136] [remote 192.168.15.203:12387] Traceback (most recent call last):
[Wed Dec 31 10:05:11.295688 2014] [:error] [pid 709:tid 140202062395136] [remote 192.168.15.203:12387]   File "/var/www/testsite/testsite/wsgi.py", line 16, in <module>
[Wed Dec 31 10:05:11.295757 2014] [:error] [pid 709:tid 140202062395136] [remote 192.168.15.203:12387]     application = get_wsgi_application()
[Wed Dec 31 10:05:11.295785 2014] [:error] [pid 709:tid 140202062395136] [remote 192.168.15.203:12387]   File "/usr/local/lib/python2.7/dist-packages/django/core/wsgi.py", line 14, in get_wsgi_application
[Wed Dec 31 10:05:11.295976 2014] [:error] [pid 709:tid 140202062395136] [remote 192.168.15.203:12387]     django.setup()
[Wed Dec 31 10:05:11.295991 2014] [:error] [pid 709:tid 140202062395136] [remote 192.168.15.203:12387]   File "/usr/local/lib/python2.7/dist-packages/django/__init__.py", line 21, in setup
[Wed Dec 31 10:05:11.296018 2014] [:error] [pid 709:tid 140202062395136] [remote 192.168.15.203:12387]     apps.populate(settings.INSTALLED_APPS)
[Wed Dec 31 10:05:11.296030 2014] [:error] [pid 709:tid 140202062395136] [remote 192.168.15.203:12387]   File "/usr/local/lib/python2.7/dist-packages/django/apps/registry.py", line 78, in populate
[Wed Dec 31 10:05:11.296076 2014] [:error] [pid 709:tid 140202062395136] [remote 192.168.15.203:12387]     raise RuntimeError("populate() isn't reentrant")
[Wed Dec 31 10:05:11.296108 2014] [:error] [pid 709:tid 140202062395136] [remote 192.168.15.203:12387] RuntimeError: populate() isn't reentrant
[Wed Dec 31 10:05:12.003909 2014] [:error] [pid 710:tid 140202062395136] [remote 192.168.15.203:12387] mod_wsgi (pid=710): Target WSGI script '/var/www/testsite/testsite/wsgi.py' cannot be loaded as Python module.
[Wed Dec 31 10:05:12.003973 2014] [:error] [pid 710:tid 140202062395136] [remote 192.168.15.203:12387] mod_wsgi (pid=710): Exception occurred processing WSGI script '/var/www/testsite/testsite/wsgi.py'.
[Wed Dec 31 10:05:12.004010 2014] [:error] [pid 710:tid 140202062395136] [remote 192.168.15.203:12387] Traceback (most recent call last):
[Wed Dec 31 10:05:12.004041 2014] [:error] [pid 710:tid 140202062395136] [remote 192.168.15.203:12387]   File "/var/www/testsite/testsite/wsgi.py", line 16, in <module>
[Wed Dec 31 10:05:12.004099 2014] [:error] [pid 710:tid 140202062395136] [remote 192.168.15.203:12387]     application = get_wsgi_application()
[Wed Dec 31 10:05:12.004111 2014] [:error] [pid 710:tid 140202062395136] [remote 192.168.15.203:12387]   File "/usr/local/lib/python2.7/dist-packages/django/core/wsgi.py", line 14, in get_wsgi_application
[Wed Dec 31 10:05:12.004141 2014] [:error] [pid 710:tid 140202062395136] [remote 192.168.15.203:12387]     django.setup()
[Wed Dec 31 10:05:12.004153 2014] [:error] [pid 710:tid 140202062395136] [remote 192.168.15.203:12387]   File "/usr/local/lib/python2.7/dist-packages/django/__init__.py", line 21, in setup
[Wed Dec 31 10:05:12.004178 2014] [:error] [pid 710:tid 140202062395136] [remote 192.168.15.203:12387]     apps.populate(settings.INSTALLED_APPS)
[Wed Dec 31 10:05:12.004190 2014] [:error] [pid 710:tid 140202062395136] [remote 192.168.15.203:12387]   File "/usr/local/lib/python2.7/dist-packages/django/apps/registry.py", line 78, in populate
[Wed Dec 31 10:05:12.004216 2014] [:error] [pid 710:tid 140202062395136] [remote 192.168.15.203:12387]     raise RuntimeError("populate() isn't reentrant")
[Wed Dec 31 10:05:12.004242 2014] [:error] [pid 710:tid 140202062395136] [remote 192.168.15.203:12387] RuntimeError: populate() isn't reentrant
[Wed Dec 31 10:05:42.888281 2014] [:error] [pid 709:tid 140202179892992] [remote 192.168.15.203:12387] mod_wsgi (pid=709): Target WSGI script '/var/www/testsite/testsite/wsgi.py' cannot be loaded as Python module.
[Wed Dec 31 10:05:42.888312 2014] [:error] [pid 709:tid 140202179892992] [remote 192.168.15.203:12387] mod_wsgi (pid=709): Exception occurred processing WSGI script '/var/www/testsite/testsite/wsgi.py'.
[Wed Dec 31 10:05:42.888337 2014] [:error] [pid 709:tid 140202179892992] [remote 192.168.15.203:12387] Traceback (most recent call last):
[Wed Dec 31 10:05:42.888337 2014] [:error] [pid 709:tid 140202179892992] [remote 192.168.15.203:12387]   File "/var/www/testsite/testsite/wsgi.py", line 16, in <module>
[Wed Dec 31 10:05:42.888337 2014] [:error] [pid 709:tid 140202179892992] [remote 192.168.15.203:12387]     application = get_wsgi_application()
[Wed Dec 31 10:05:42.888337 2014] [:error] [pid 709:tid 140202179892992] [remote 192.168.15.203:12387]   File "/usr/local/lib/python2.7/dist-packages/django/core/wsgi.py", line 14, in get_wsgi_application
[Wed Dec 31 10:05:42.888337 2014] [:error] [pid 709:tid 140202179892992] [remote 192.168.15.203:12387]     django.setup()
[Wed Dec 31 10:05:42.888337 2014] [:error] [pid 709:tid 140202179892992] [remote 192.168.15.203:12387]   File "/usr/local/lib/python2.7/dist-packages/django/__init__.py", line 21, in setup
[Wed Dec 31 10:05:42.888337 2014] [:error] [pid 709:tid 140202179892992] [remote 192.168.15.203:12387]     apps.populate(settings.INSTALLED_APPS)
[Wed Dec 31 10:05:42.888337 2014] [:error] [pid 709:tid 140202179892992] [remote 192.168.15.203:12387]   File "/usr/local/lib/python2.7/dist-packages/django/apps/registry.py", line 78, in populate
[Wed Dec 31 10:05:42.888337 2014] [:error] [pid 709:tid 140202179892992] [remote 192.168.15.203:12387]     raise RuntimeError("populate() isn't reentrant")
[Wed Dec 31 10:05:42.888337 2014] [:error] [pid 709:tid 140202179892992] [remote 192.168.15.203:12387] RuntimeError: populate() isn't reentrant
[Wed Dec 31 10:05:46.276955 2014] [:error] [pid 710:tid 140202179892992] [remote 192.168.15.203:12387] mod_wsgi (pid=710): Target WSGI script '/var/www/testsite/testsite/wsgi.py' cannot be loaded as Python module.
[Wed Dec 31 10:05:46.276982 2014] [:error] [pid 710:tid 140202179892992] [remote 192.168.15.203:12387] mod_wsgi (pid=710): Exception occurred processing WSGI script '/var/www/testsite/testsite/wsgi.py'.
[Wed Dec 31 10:05:46.277001 2014] [:error] [pid 710:tid 140202179892992] [remote 192.168.15.203:12387] Traceback (most recent call last):
[Wed Dec 31 10:05:46.277022 2014] [:error] [pid 710:tid 140202179892992] [remote 192.168.15.203:12387]   File "/var/www/testsite/testsite/wsgi.py", line 16, in <module>
[Wed Dec 31 10:05:46.277050 2014] [:error] [pid 710:tid 140202179892992] [remote 192.168.15.203:12387]     application = get_wsgi_application()
[Wed Dec 31 10:05:46.277061 2014] [:error] [pid 710:tid 140202179892992] [remote 192.168.15.203:12387]   File "/usr/local/lib/python2.7/dist-packages/django/core/wsgi.py", line 14, in get_wsgi_application
[Wed Dec 31 10:05:46.277081 2014] [:error] [pid 710:tid 140202179892992] [remote 192.168.15.203:12387]     django.setup()
[Wed Dec 31 10:05:46.277092 2014] [:error] [pid 710:tid 140202179892992] [remote 192.168.15.203:12387]   File "/usr/local/lib/python2.7/dist-packages/django/__init__.py", line 21, in setup
[Wed Dec 31 10:05:46.277109 2014] [:error] [pid 710:tid 140202179892992] [remote 192.168.15.203:12387]     apps.populate(settings.INSTALLED_APPS)
[Wed Dec 31 10:05:46.277119 2014] [:error] [pid 710:tid 140202179892992] [remote 192.168.15.203:12387]   File "/usr/local/lib/python2.7/dist-packages/django/apps/registry.py", line 78, in populate
[Wed Dec 31 10:05:46.277137 2014] [:error] [pid 710:tid 140202179892992] [remote 192.168.15.203:12387]     raise RuntimeError("populate() isn't reentrant")
[Wed Dec 31 10:05:46.277154 2014] [:error] [pid 710:tid 140202179892992] [remote 192.168.15.203:12387] RuntimeError: populate() isn't reentrant
[Wed Dec 31 10:07:42.193337 2014] [:error] [pid 1137:tid 140421827139328] [remote 192.168.15.203:51591] mod_wsgi (pid=1137): Target WSGI script '/var/www/testsite/testsite/wsgi.py' cannot be loaded as Python module.
[Wed Dec 31 10:07:42.193607 2014] [:error] [pid 1137:tid 140421827139328] [remote 192.168.15.203:51591] mod_wsgi (pid=1137): Exception occurred processing WSGI script '/var/www/testsite/testsite/wsgi.py'.
[Wed Dec 31 10:07:42.193650 2014] [:error] [pid 1137:tid 140421827139328] [remote 192.168.15.203:51591] Traceback (most recent call last):
[Wed Dec 31 10:07:42.193670 2014] [:error] [pid 1137:tid 140421827139328] [remote 192.168.15.203:51591]   File "/var/www/testsite/testsite/wsgi.py", line 16, in <module>
[Wed Dec 31 10:07:42.193724 2014] [:error] [pid 1137:tid 140421827139328] [remote 192.168.15.203:51591]     application = get_wsgi_application()
[Wed Dec 31 10:07:42.193772 2014] [:error] [pid 1137:tid 140421827139328] [remote 192.168.15.203:51591]   File "/usr/local/lib/python2.7/dist-packages/django/core/wsgi.py", line 14, in get_wsgi_application
[Wed Dec 31 10:07:42.193822 2014] [:error] [pid 1137:tid 140421827139328] [remote 192.168.15.203:51591]     django.setup()
[Wed Dec 31 10:07:42.193835 2014] [:error] [pid 1137:tid 140421827139328] [remote 192.168.15.203:51591]   File "/usr/local/lib/python2.7/dist-packages/django/__init__.py", line 21, in setup
[Wed Dec 31 10:07:42.193899 2014] [:error] [pid 1137:tid 140421827139328] [remote 192.168.15.203:51591]     apps.populate(settings.INSTALLED_APPS)
[Wed Dec 31 10:07:42.193912 2014] [:error] [pid 1137:tid 140421827139328] [remote 192.168.15.203:51591]   File "/usr/local/lib/python2.7/dist-packages/django/apps/registry.py", line 115, in populate
[Wed Dec 31 10:07:42.194169 2014] [:error] [pid 1137:tid 140421827139328] [remote 192.168.15.203:51591]     app_config.ready()
[Wed Dec 31 10:07:42.194182 2014] [:error] [pid 1137:tid 140421827139328] [remote 192.168.15.203:51591]   File "/usr/local/lib/python2.7/dist-packages/django/contrib/admin/apps.py", line 22, in ready
[Wed Dec 31 10:07:42.194252 2014] [:error] [pid 1137:tid 140421827139328] [remote 192.168.15.203:51591]     self.module.autodiscover()
[Wed Dec 31 10:07:42.194264 2014] [:error] [pid 1137:tid 140421827139328] [remote 192.168.15.203:51591]   File "/usr/local/lib/python2.7/dist-packages/django/contrib/admin/__init__.py", line 23, in autodiscover
[Wed Dec 31 10:07:42.194340 2014] [:error] [pid 1137:tid 140421827139328] [remote 192.168.15.203:51591]     autodiscover_modules('admin', register_to=site)
[Wed Dec 31 10:07:42.194352 2014] [:error] [pid 1137:tid 140421827139328] [remote 192.168.15.203:51591]   File "/usr/local/lib/python2.7/dist-packages/django/utils/module_loading.py", line 74, in autodiscover_modules
[Wed Dec 31 10:07:42.194525 2014] [:error] [pid 1137:tid 140421827139328] [remote 192.168.15.203:51591]     import_module('%s.%s' % (app_config.name, module_to_search))
[Wed Dec 31 10:07:42.194538 2014] [:error] [pid 1137:tid 140421827139328] [remote 192.168.15.203:51591]   File "/usr/lib/python2.7/importlib/__init__.py", line 37, in import_module
[Wed Dec 31 10:07:42.194616 2014] [:error] [pid 1137:tid 140421827139328] [remote 192.168.15.203:51591]     __import__(name)
[Wed Dec 31 10:07:42.194627 2014] [:error] [pid 1137:tid 140421827139328] [remote 192.168.15.203:51591]   File "/var/www/testsite/polls/admin.py", line 2, in <module>
[Wed Dec 31 10:07:42.194666 2014] [:error] [pid 1137:tid 140421827139328] [remote 192.168.15.203:51591]     from testsite.polls.models import Choice, Question
[Wed Dec 31 10:07:42.194684 2014] [:error] [pid 1137:tid 140421827139328] [remote 192.168.15.203:51591] ImportError: No module named polls.models
[Wed Dec 31 10:09:35.495511 2014] [:error] [pid 1138:tid 140421835532032] [remote 192.168.15.203:51591] mod_wsgi (pid=1138): Target WSGI script '/var/www/testsite/testsite/wsgi.py' cannot be loaded as Python module.
[Wed Dec 31 10:09:35.495729 2014] [:error] [pid 1138:tid 140421835532032] [remote 192.168.15.203:51591] mod_wsgi (pid=1138): Exception occurred processing WSGI script '/var/www/testsite/testsite/wsgi.py'.
[Wed Dec 31 10:09:35.495775 2014] [:error] [pid 1138:tid 140421835532032] [remote 192.168.15.203:51591] Traceback (most recent call last):
[Wed Dec 31 10:09:35.495803 2014] [:error] [pid 1138:tid 140421835532032] [remote 192.168.15.203:51591]   File "/var/www/testsite/testsite/wsgi.py", line 16, in <module>
[Wed Dec 31 10:09:35.495861 2014] [:error] [pid 1138:tid 140421835532032] [remote 192.168.15.203:51591]     application = get_wsgi_application()
[Wed Dec 31 10:09:35.496012 2014] [:error] [pid 1138:tid 140421835532032] [remote 192.168.15.203:51591]   File "/usr/local/lib/python2.7/dist-packages/django/core/wsgi.py", line 14, in get_wsgi_application
[Wed Dec 31 10:09:35.496069 2014] [:error] [pid 1138:tid 140421835532032] [remote 192.168.15.203:51591]     django.setup()
[Wed Dec 31 10:09:35.496082 2014] [:error] [pid 1138:tid 140421835532032] [remote 192.168.15.203:51591]   File "/usr/local/lib/python2.7/dist-packages/django/__init__.py", line 21, in setup
[Wed Dec 31 10:09:35.496145 2014] [:error] [pid 1138:tid 140421835532032] [remote 192.168.15.203:51591]     apps.populate(settings.INSTALLED_APPS)
[Wed Dec 31 10:09:35.496158 2014] [:error] [pid 1138:tid 140421835532032] [remote 192.168.15.203:51591]   File "/usr/local/lib/python2.7/dist-packages/django/apps/registry.py", line 115, in populate
[Wed Dec 31 10:09:35.496430 2014] [:error] [pid 1138:tid 140421835532032] [remote 192.168.15.203:51591]     app_config.ready()
[Wed Dec 31 10:09:35.496443 2014] [:error] [pid 1138:tid 140421835532032] [remote 192.168.15.203:51591]   File "/usr/local/lib/python2.7/dist-packages/django/contrib/admin/apps.py", line 22, in ready
[Wed Dec 31 10:09:35.496514 2014] [:error] [pid 1138:tid 140421835532032] [remote 192.168.15.203:51591]     self.module.autodiscover()
[Wed Dec 31 10:09:35.496527 2014] [:error] [pid 1138:tid 140421835532032] [remote 192.168.15.203:51591]   File "/usr/local/lib/python2.7/dist-packages/django/contrib/admin/__init__.py", line 23, in autodiscover
[Wed Dec 31 10:09:35.496603 2014] [:error] [pid 1138:tid 140421835532032] [remote 192.168.15.203:51591]     autodiscover_modules('admin', register_to=site)
[Wed Dec 31 10:09:35.496615 2014] [:error] [pid 1138:tid 140421835532032] [remote 192.168.15.203:51591]   File "/usr/local/lib/python2.7/dist-packages/django/utils/module_loading.py", line 74, in autodiscover_modules
[Wed Dec 31 10:09:35.496780 2014] [:error] [pid 1138:tid 140421835532032] [remote 192.168.15.203:51591]     import_module('%s.%s' % (app_config.name, module_to_search))
[Wed Dec 31 10:09:35.496793 2014] [:error] [pid 1138:tid 140421835532032] [remote 192.168.15.203:51591]   File "/usr/lib/python2.7/importlib/__init__.py", line 37, in import_module
[Wed Dec 31 10:09:35.496874 2014] [:error] [pid 1138:tid 140421835532032] [remote 192.168.15.203:51591]     __import__(name)
[Wed Dec 31 10:09:35.496886 2014] [:error] [pid 1138:tid 140421835532032] [remote 192.168.15.203:51591]   File "/var/www/testsite/polls/admin.py", line 2, in <module>
[Wed Dec 31 10:09:35.496924 2014] [:error] [pid 1138:tid 140421835532032] [remote 192.168.15.203:51591]     from testsite.polls.models import Choice, Question
[Wed Dec 31 10:09:35.496945 2014] [:error] [pid 1138:tid 140421835532032] [remote 192.168.15.203:51591] ImportError: No module named polls.models
[Wed Dec 31 10:09:36.180016 2014] [:error] [pid 1137:tid 140421718034176] [remote 192.168.15.203:45191] mod_wsgi (pid=1137): Target WSGI script '/var/www/testsite/testsite/wsgi.py' cannot be loaded as Python module.
[Wed Dec 31 10:09:36.180143 2014] [:error] [pid 1137:tid 140421718034176] [remote 192.168.15.203:45191] mod_wsgi (pid=1137): Exception occurred processing WSGI script '/var/www/testsite/testsite/wsgi.py'.
[Wed Dec 31 10:09:36.180179 2014] [:error] [pid 1137:tid 140421718034176] [remote 192.168.15.203:45191] Traceback (most recent call last):
[Wed Dec 31 10:09:36.180238 2014] [:error] [pid 1137:tid 140421718034176] [remote 192.168.15.203:45191]   File "/var/www/testsite/testsite/wsgi.py", line 16, in <module>
[Wed Dec 31 10:09:36.180283 2014] [:error] [pid 1137:tid 140421718034176] [remote 192.168.15.203:45191]     application = get_wsgi_application()
[Wed Dec 31 10:09:36.180295 2014] [:error] [pid 1137:tid 140421718034176] [remote 192.168.15.203:45191]   File "/usr/local/lib/python2.7/dist-packages/django/core/wsgi.py", line 14, in get_wsgi_application
[Wed Dec 31 10:09:36.180326 2014] [:error] [pid 1137:tid 140421718034176] [remote 192.168.15.203:45191]     django.setup()
[Wed Dec 31 10:09:36.180338 2014] [:error] [pid 1137:tid 140421718034176] [remote 192.168.15.203:45191]   File "/usr/local/lib/python2.7/dist-packages/django/__init__.py", line 21, in setup
[Wed Dec 31 10:09:36.180363 2014] [:error] [pid 1137:tid 140421718034176] [remote 192.168.15.203:45191]     apps.populate(settings.INSTALLED_APPS)
[Wed Dec 31 10:09:36.180374 2014] [:error] [pid 1137:tid 140421718034176] [remote 192.168.15.203:45191]   File "/usr/local/lib/python2.7/dist-packages/django/apps/registry.py", line 78, in populate
[Wed Dec 31 10:09:36.180437 2014] [:error] [pid 1137:tid 140421718034176] [remote 192.168.15.203:45191]     raise RuntimeError("populate() isn't reentrant")
[Wed Dec 31 10:09:36.180456 2014] [:error] [pid 1137:tid 140421718034176] [remote 192.168.15.203:45191] RuntimeError: populate() isn't reentrant
[Wed Dec 31 10:14:56.178755 2014] [:error] [pid 1138:tid 140421718034176] [remote 192.168.15.203:44935] mod_wsgi (pid=1138): Target WSGI script '/var/www/testsite/testsite/wsgi.py' cannot be loaded as Python module.
[Wed Dec 31 10:14:56.178846 2014] [:error] [pid 1138:tid 140421718034176] [remote 192.168.15.203:44935] mod_wsgi (pid=1138): Exception occurred processing WSGI script '/var/www/testsite/testsite/wsgi.py'.
[Wed Dec 31 10:14:56.178876 2014] [:error] [pid 1138:tid 140421718034176] [remote 192.168.15.203:44935] Traceback (most recent call last):
[Wed Dec 31 10:14:56.178926 2014] [:error] [pid 1138:tid 140421718034176] [remote 192.168.15.203:44935]   File "/var/www/testsite/testsite/wsgi.py", line 16, in <module>
[Wed Dec 31 10:14:56.178973 2014] [:error] [pid 1138:tid 140421718034176] [remote 192.168.15.203:44935]     application = get_wsgi_application()
[Wed Dec 31 10:14:56.178985 2014] [:error] [pid 1138:tid 140421718034176] [remote 192.168.15.203:44935]   File "/usr/local/lib/python2.7/dist-packages/django/core/wsgi.py", line 14, in get_wsgi_application
[Wed Dec 31 10:14:56.179052 2014] [:error] [pid 1138:tid 140421718034176] [remote 192.168.15.203:44935]     django.setup()
[Wed Dec 31 10:14:56.179064 2014] [:error] [pid 1138:tid 140421718034176] [remote 192.168.15.203:44935]   File "/usr/local/lib/python2.7/dist-packages/django/__init__.py", line 21, in setup
[Wed Dec 31 10:14:56.179083 2014] [:error] [pid 1138:tid 140421718034176] [remote 192.168.15.203:44935]     apps.populate(settings.INSTALLED_APPS)
[Wed Dec 31 10:14:56.179094 2014] [:error] [pid 1138:tid 140421718034176] [remote 192.168.15.203:44935]   File "/usr/local/lib/python2.7/dist-packages/django/apps/registry.py", line 78, in populate
[Wed Dec 31 10:14:56.179131 2014] [:error] [pid 1138:tid 140421718034176] [remote 192.168.15.203:44935]     raise RuntimeError("populate() isn't reentrant")
[Wed Dec 31 10:14:56.179157 2014] [:error] [pid 1138:tid 140421718034176] [remote 192.168.15.203:44935] RuntimeError: populate() isn't reentrant
[Wed Dec 31 10:14:56.729273 2014] [:error] [pid 1137:tid 140421827139328] [remote 192.168.15.203:45191] mod_wsgi (pid=1137): Target WSGI script '/var/www/testsite/testsite/wsgi.py' cannot be loaded as Python module.
[Wed Dec 31 10:14:56.729322 2014] [:error] [pid 1137:tid 140421827139328] [remote 192.168.15.203:45191] mod_wsgi (pid=1137): Exception occurred processing WSGI script '/var/www/testsite/testsite/wsgi.py'.
[Wed Dec 31 10:14:56.729350 2014] [:error] [pid 1137:tid 140421827139328] [remote 192.168.15.203:45191] Traceback (most recent call last):
[Wed Dec 31 10:14:56.729414 2014] [:error] [pid 1137:tid 140421827139328] [remote 192.168.15.203:45191]   File "/var/www/testsite/testsite/wsgi.py", line 16, in <module>
[Wed Dec 31 10:14:56.729452 2014] [:error] [pid 1137:tid 140421827139328] [remote 192.168.15.203:45191]     application = get_wsgi_application()
[Wed Dec 31 10:14:56.729464 2014] [:error] [pid 1137:tid 140421827139328] [remote 192.168.15.203:45191]   File "/usr/local/lib/python2.7/dist-packages/django/core/wsgi.py", line 14, in get_wsgi_application
[Wed Dec 31 10:14:56.729485 2014] [:error] [pid 1137:tid 140421827139328] [remote 192.168.15.203:45191]     django.setup()
[Wed Dec 31 10:14:56.729497 2014] [:error] [pid 1137:tid 140421827139328] [remote 192.168.15.203:45191]   File "/usr/local/lib/python2.7/dist-packages/django/__init__.py", line 21, in setup
[Wed Dec 31 10:14:56.729514 2014] [:error] [pid 1137:tid 140421827139328] [remote 192.168.15.203:45191]     apps.populate(settings.INSTALLED_APPS)
[Wed Dec 31 10:14:56.729525 2014] [:error] [pid 1137:tid 140421827139328] [remote 192.168.15.203:45191]   File "/usr/local/lib/python2.7/dist-packages/django/apps/registry.py", line 78, in populate
[Wed Dec 31 10:14:56.729554 2014] [:error] [pid 1137:tid 140421827139328] [remote 192.168.15.203:45191]     raise RuntimeError("populate() isn't reentrant")
[Wed Dec 31 10:14:56.729572 2014] [:error] [pid 1137:tid 140421827139328] [remote 192.168.15.203:45191] RuntimeError: populate() isn't reentrant
[Wed Dec 31 10:18:31.940949 2014] [:error] [pid 1138:tid 140421835532032] [remote 192.168.15.203:44935] mod_wsgi (pid=1138): Target WSGI script '/var/www/testsite/testsite/wsgi.py' cannot be loaded as Python module.
[Wed Dec 31 10:18:31.941058 2014] [:error] [pid 1138:tid 140421835532032] [remote 192.168.15.203:44935] mod_wsgi (pid=1138): Exception occurred processing WSGI script '/var/www/testsite/testsite/wsgi.py'.
[Wed Dec 31 10:18:31.941098 2014] [:error] [pid 1138:tid 140421835532032] [remote 192.168.15.203:44935] Traceback (most recent call last):
[Wed Dec 31 10:18:31.941138 2014] [:error] [pid 1138:tid 140421835532032] [remote 192.168.15.203:44935]   File "/var/www/testsite/testsite/wsgi.py", line 16, in <module>
[Wed Dec 31 10:18:31.941194 2014] [:error] [pid 1138:tid 140421835532032] [remote 192.168.15.203:44935]     application = get_wsgi_application()
[Wed Dec 31 10:18:31.941208 2014] [:error] [pid 1138:tid 140421835532032] [remote 192.168.15.203:44935]   File "/usr/local/lib/python2.7/dist-packages/django/core/wsgi.py", line 14, in get_wsgi_application
[Wed Dec 31 10:18:31.941236 2014] [:error] [pid 1138:tid 140421835532032] [remote 192.168.15.203:44935]     django.setup()
[Wed Dec 31 10:18:31.941248 2014] [:error] [pid 1138:tid 140421835532032] [remote 192.168.15.203:44935]   File "/usr/local/lib/python2.7/dist-packages/django/__init__.py", line 21, in setup
[Wed Dec 31 10:18:31.941272 2014] [:error] [pid 1138:tid 140421835532032] [remote 192.168.15.203:44935]     apps.populate(settings.INSTALLED_APPS)
[Wed Dec 31 10:18:31.941284 2014] [:error] [pid 1138:tid 140421835532032] [remote 192.168.15.203:44935]   File "/usr/local/lib/python2.7/dist-packages/django/apps/registry.py", line 78, in populate
[Wed Dec 31 10:18:31.941309 2014] [:error] [pid 1138:tid 140421835532032] [remote 192.168.15.203:44935]     raise RuntimeError("populate() isn't reentrant")
[Wed Dec 31 10:18:31.941328 2014] [:error] [pid 1138:tid 140421835532032] [remote 192.168.15.203:44935] RuntimeError: populate() isn't reentrant
[Wed Dec 31 10:18:32.931172 2014] [:error] [pid 1137:tid 140421718034176] [remote 192.168.15.203:45191] mod_wsgi (pid=1137): Target WSGI script '/var/www/testsite/testsite/wsgi.py' cannot be loaded as Python module.
[Wed Dec 31 10:18:32.931232 2014] [:error] [pid 1137:tid 140421718034176] [remote 192.168.15.203:45191] mod_wsgi (pid=1137): Exception occurred processing WSGI script '/var/www/testsite/testsite/wsgi.py'.
[Wed Dec 31 10:18:32.931277 2014] [:error] [pid 1137:tid 140421718034176] [remote 192.168.15.203:45191] Traceback (most recent call last):
[Wed Dec 31 10:18:32.931313 2014] [:error] [pid 1137:tid 140421718034176] [remote 192.168.15.203:45191]   File "/var/www/testsite/testsite/wsgi.py", line 16, in <module>
[Wed Dec 31 10:18:32.931376 2014] [:error] [pid 1137:tid 140421718034176] [remote 192.168.15.203:45191]     application = get_wsgi_application()
[Wed Dec 31 10:18:32.931388 2014] [:error] [pid 1137:tid 140421718034176] [remote 192.168.15.203:45191]   File "/usr/local/lib/python2.7/dist-packages/django/core/wsgi.py", line 14, in get_wsgi_application
[Wed Dec 31 10:18:32.931416 2014] [:error] [pid 1137:tid 140421718034176] [remote 192.168.15.203:45191]     django.setup()
[Wed Dec 31 10:18:32.931429 2014] [:error] [pid 1137:tid 140421718034176] [remote 192.168.15.203:45191]   File "/usr/local/lib/python2.7/dist-packages/django/__init__.py", line 21, in setup
[Wed Dec 31 10:18:32.931454 2014] [:error] [pid 1137:tid 140421718034176] [remote 192.168.15.203:45191]     apps.populate(settings.INSTALLED_APPS)
[Wed Dec 31 10:18:32.931465 2014] [:error] [pid 1137:tid 140421718034176] [remote 192.168.15.203:45191]   File "/usr/local/lib/python2.7/dist-packages/django/apps/registry.py", line 78, in populate
[Wed Dec 31 10:18:32.931587 2014] [:error] [pid 1137:tid 140421718034176] [remote 192.168.15.203:45191]     raise RuntimeError("populate() isn't reentrant")
[Wed Dec 31 10:18:32.931605 2014] [:error] [pid 1137:tid 140421718034176] [remote 192.168.15.203:45191] RuntimeError: populate() isn't reentrant
[Wed Dec 31 10:18:33.481035 2014] [:error] [pid 1138:tid 140421718034176] [remote 192.168.15.203:44935] mod_wsgi (pid=1138): Target WSGI script '/var/www/testsite/testsite/wsgi.py' cannot be loaded as Python module.
[Wed Dec 31 10:18:33.481951 2014] [:error] [pid 1138:tid 140421718034176] [remote 192.168.15.203:44935] mod_wsgi (pid=1138): Exception occurred processing WSGI script '/var/www/testsite/testsite/wsgi.py'.
[Wed Dec 31 10:18:33.481976 2014] [:error] [pid 1138:tid 140421718034176] [remote 192.168.15.203:44935] Traceback (most recent call last):
[Wed Dec 31 10:18:33.481999 2014] [:error] [pid 1138:tid 140421718034176] [remote 192.168.15.203:44935]   File "/var/www/testsite/testsite/wsgi.py", line 16, in <module>
[Wed Dec 31 10:18:33.482032 2014] [:error] [pid 1138:tid 140421718034176] [remote 192.168.15.203:44935]     application = get_wsgi_application()
[Wed Dec 31 10:18:33.482043 2014] [:error] [pid 1138:tid 140421718034176] [remote 192.168.15.203:44935]   File "/usr/local/lib/python2.7/dist-packages/django/core/wsgi.py", line 14, in get_wsgi_application
[Wed Dec 31 10:18:33.482063 2014] [:error] [pid 1138:tid 140421718034176] [remote 192.168.15.203:44935]     django.setup()
[Wed Dec 31 10:18:33.482074 2014] [:error] [pid 1138:tid 140421718034176] [remote 192.168.15.203:44935]   File "/usr/local/lib/python2.7/dist-packages/django/__init__.py", line 21, in setup
[Wed Dec 31 10:18:33.482092 2014] [:error] [pid 1138:tid 140421718034176] [remote 192.168.15.203:44935]     apps.populate(settings.INSTALLED_APPS)
[Wed Dec 31 10:18:33.482103 2014] [:error] [pid 1138:tid 140421718034176] [remote 192.168.15.203:44935]   File "/usr/local/lib/python2.7/dist-packages/django/apps/registry.py", line 78, in populate
[Wed Dec 31 10:18:33.482120 2014] [:error] [pid 1138:tid 140421718034176] [remote 192.168.15.203:44935]     raise RuntimeError("populate() isn't reentrant")
[Wed Dec 31 10:18:33.482137 2014] [:error] [pid 1138:tid 140421718034176] [remote 192.168.15.203:44935] RuntimeError: populate() isn't reentrant
[Wed Dec 31 10:18:35.552562 2014] [:error] [pid 1137:tid 140421827139328] [remote 192.168.15.203:45191] mod_wsgi (pid=1137): Target WSGI script '/var/www/testsite/testsite/wsgi.py' cannot be loaded as Python module.
[Wed Dec 31 10:18:35.552609 2014] [:error] [pid 1137:tid 140421827139328] [remote 192.168.15.203:45191] mod_wsgi (pid=1137): Exception occurred processing WSGI script '/var/www/testsite/testsite/wsgi.py'.
[Wed Dec 31 10:18:35.552638 2014] [:error] [pid 1137:tid 140421827139328] [remote 192.168.15.203:45191] Traceback (most recent call last):
[Wed Dec 31 10:18:35.552668 2014] [:error] [pid 1137:tid 140421827139328] [remote 192.168.15.203:45191]   File "/var/www/testsite/testsite/wsgi.py", line 16, in <module>
[Wed Dec 31 10:18:35.552705 2014] [:error] [pid 1137:tid 140421827139328] [remote 192.168.15.203:45191]     application = get_wsgi_application()
[Wed Dec 31 10:18:35.552716 2014] [:error] [pid 1137:tid 140421827139328] [remote 192.168.15.203:45191]   File "/usr/local/lib/python2.7/dist-packages/django/core/wsgi.py", line 14, in get_wsgi_application
[Wed Dec 31 10:18:35.552738 2014] [:error] [pid 1137:tid 140421827139328] [remote 192.168.15.203:45191]     django.setup()
[Wed Dec 31 10:18:35.552749 2014] [:error] [pid 1137:tid 140421827139328] [remote 192.168.15.203:45191]   File "/usr/local/lib/python2.7/dist-packages/django/__init__.py", line 21, in setup
[Wed Dec 31 10:18:35.552767 2014] [:error] [pid 1137:tid 140421827139328] [remote 192.168.15.203:45191]     apps.populate(settings.INSTALLED_APPS)
[Wed Dec 31 10:18:35.552777 2014] [:error] [pid 1137:tid 140421827139328] [remote 192.168.15.203:45191]   File "/usr/local/lib/python2.7/dist-packages/django/apps/registry.py", line 78, in populate
[Wed Dec 31 10:18:35.552896 2014] [:error] [pid 1137:tid 140421827139328] [remote 192.168.15.203:45191]     raise RuntimeError("populate() isn't reentrant")
[Wed Dec 31 10:18:35.552918 2014] [:error] [pid 1137:tid 140421827139328] [remote 192.168.15.203:45191] RuntimeError: populate() isn't reentrant
[Wed Dec 31 10:18:36.119044 2014] [:error] [pid 1138:tid 140421835532032] [remote 192.168.15.203:44935] mod_wsgi (pid=1138): Target WSGI script '/var/www/testsite/testsite/wsgi.py' cannot be loaded as Python module.
[Wed Dec 31 10:18:36.119076 2014] [:error] [pid 1138:tid 140421835532032] [remote 192.168.15.203:44935] mod_wsgi (pid=1138): Exception occurred processing WSGI script '/var/www/testsite/testsite/wsgi.py'.
[Wed Dec 31 10:18:36.119097 2014] [:error] [pid 1138:tid 140421835532032] [remote 192.168.15.203:44935] Traceback (most recent call last):
[Wed Dec 31 10:18:36.119207 2014] [:error] [pid 1138:tid 140421835532032] [remote 192.168.15.203:44935]   File "/var/www/testsite/testsite/wsgi.py", line 16, in <module>
[Wed Dec 31 10:18:36.119239 2014] [:error] [pid 1138:tid 140421835532032] [remote 192.168.15.203:44935]     application = get_wsgi_application()
[Wed Dec 31 10:18:36.119250 2014] [:error] [pid 1138:tid 140421835532032] [remote 192.168.15.203:44935]   File "/usr/local/lib/python2.7/dist-packages/django/core/wsgi.py", line 14, in get_wsgi_application
[Wed Dec 31 10:18:36.119271 2014] [:error] [pid 1138:tid 140421835532032] [remote 192.168.15.203:44935]     django.setup()
[Wed Dec 31 10:18:36.119282 2014] [:error] [pid 1138:tid 140421835532032] [remote 192.168.15.203:44935]   File "/usr/local/lib/python2.7/dist-packages/django/__init__.py", line 21, in setup
[Wed Dec 31 10:18:36.119299 2014] [:error] [pid 1138:tid 140421835532032] [remote 192.168.15.203:44935]     apps.populate(settings.INSTALLED_APPS)
[Wed Dec 31 10:18:36.119310 2014] [:error] [pid 1138:tid 140421835532032] [remote 192.168.15.203:44935]   File "/usr/local/lib/python2.7/dist-packages/django/apps/registry.py", line 78, in populate
[Wed Dec 31 10:18:36.119328 2014] [:error] [pid 1138:tid 140421835532032] [remote 192.168.15.203:44935]     raise RuntimeError("populate() isn't reentrant")
[Wed Dec 31 10:18:36.119345 2014] [:error] [pid 1138:tid 140421835532032] [remote 192.168.15.203:44935] RuntimeError: populate() isn't reentrant
[Wed Dec 31 10:18:41.922412 2014] [:error] [pid 1138:tid 140421718034176] [remote 192.168.15.203:44679] mod_wsgi (pid=1138): Target WSGI script '/var/www/testsite/testsite/wsgi.py' cannot be loaded as Python module.
[Wed Dec 31 10:18:41.922449 2014] [:error] [pid 1138:tid 140421718034176] [remote 192.168.15.203:44679] mod_wsgi (pid=1138): Exception occurred processing WSGI script '/var/www/testsite/testsite/wsgi.py'.
[Wed Dec 31 10:18:41.922471 2014] [:error] [pid 1138:tid 140421718034176] [remote 192.168.15.203:44679] Traceback (most recent call last):
[Wed Dec 31 10:18:41.922496 2014] [:error] [pid 1138:tid 140421718034176] [remote 192.168.15.203:44679]   File "/var/www/testsite/testsite/wsgi.py", line 16, in <module>
[Wed Dec 31 10:18:41.922530 2014] [:error] [pid 1138:tid 140421718034176] [remote 192.168.15.203:44679]     application = get_wsgi_application()
[Wed Dec 31 10:18:41.922541 2014] [:error] [pid 1138:tid 140421718034176] [remote 192.168.15.203:44679]   File "/usr/local/lib/python2.7/dist-packages/django/core/wsgi.py", line 14, in get_wsgi_application
[Wed Dec 31 10:18:41.922587 2014] [:error] [pid 1138:tid 140421718034176] [remote 192.168.15.203:44679]     django.setup()
[Wed Dec 31 10:18:41.922599 2014] [:error] [pid 1138:tid 140421718034176] [remote 192.168.15.203:44679]   File "/usr/local/lib/python2.7/dist-packages/django/__init__.py", line 21, in setup
[Wed Dec 31 10:18:41.922617 2014] [:error] [pid 1138:tid 140421718034176] [remote 192.168.15.203:44679]     apps.populate(settings.INSTALLED_APPS)
[Wed Dec 31 10:18:41.922629 2014] [:error] [pid 1138:tid 140421718034176] [remote 192.168.15.203:44679]   File "/usr/local/lib/python2.7/dist-packages/django/apps/registry.py", line 78, in populate
[Wed Dec 31 10:18:41.922666 2014] [:error] [pid 1138:tid 140421718034176] [remote 192.168.15.203:44679]     raise RuntimeError("populate() isn't reentrant")
[Wed Dec 31 10:18:41.922685 2014] [:error] [pid 1138:tid 140421718034176] [remote 192.168.15.203:44679] RuntimeError: populate() isn't reentrant
[Wed Dec 31 10:28:21.498375 2014] [:error] [pid 1137:tid 140421718034176] [remote 192.168.15.203:45191] mod_wsgi (pid=1137): Target WSGI script '/var/www/testsite/testsite/wsgi.py' cannot be loaded as Python module.
[Wed Dec 31 10:28:21.498472 2014] [:error] [pid 1137:tid 140421718034176] [remote 192.168.15.203:45191] mod_wsgi (pid=1137): Exception occurred processing WSGI script '/var/www/testsite/testsite/wsgi.py'.
[Wed Dec 31 10:28:21.498520 2014] [:error] [pid 1137:tid 140421718034176] [remote 192.168.15.203:45191] Traceback (most recent call last):
[Wed Dec 31 10:28:21.498563 2014] [:error] [pid 1137:tid 140421718034176] [remote 192.168.15.203:45191]   File "/var/www/testsite/testsite/wsgi.py", line 16, in <module>
[Wed Dec 31 10:28:21.498623 2014] [:error] [pid 1137:tid 140421718034176] [remote 192.168.15.203:45191]     application = get_wsgi_application()
[Wed Dec 31 10:28:21.498636 2014] [:error] [pid 1137:tid 140421718034176] [remote 192.168.15.203:45191]   File "/usr/local/lib/python2.7/dist-packages/django/core/wsgi.py", line 14, in get_wsgi_application
[Wed Dec 31 10:28:21.498699 2014] [:error] [pid 1137:tid 140421718034176] [remote 192.168.15.203:45191]     django.setup()
[Wed Dec 31 10:28:21.498712 2014] [:error] [pid 1137:tid 140421718034176] [remote 192.168.15.203:45191]   File "/usr/local/lib/python2.7/dist-packages/django/__init__.py", line 21, in setup
[Wed Dec 31 10:28:21.498740 2014] [:error] [pid 1137:tid 140421718034176] [remote 192.168.15.203:45191]     apps.populate(settings.INSTALLED_APPS)
[Wed Dec 31 10:28:21.498752 2014] [:error] [pid 1137:tid 140421718034176] [remote 192.168.15.203:45191]   File "/usr/local/lib/python2.7/dist-packages/django/apps/registry.py", line 78, in populate
[Wed Dec 31 10:28:21.498797 2014] [:error] [pid 1137:tid 140421718034176] [remote 192.168.15.203:45191]     raise RuntimeError("populate() isn't reentrant")
[Wed Dec 31 10:28:21.498816 2014] [:error] [pid 1137:tid 140421718034176] [remote 192.168.15.203:45191] RuntimeError: populate() isn't reentrant
[Wed Dec 31 10:28:22.281916 2014] [:error] [pid 1138:tid 140421835532032] [remote 192.168.15.203:44679] mod_wsgi (pid=1138): Target WSGI script '/var/www/testsite/testsite/wsgi.py' cannot be loaded as Python module.
[Wed Dec 31 10:28:22.281975 2014] [:error] [pid 1138:tid 140421835532032] [remote 192.168.15.203:44679] mod_wsgi (pid=1138): Exception occurred processing WSGI script '/var/www/testsite/testsite/wsgi.py'.
[Wed Dec 31 10:28:22.282015 2014] [:error] [pid 1138:tid 140421835532032] [remote 192.168.15.203:44679] Traceback (most recent call last):
[Wed Dec 31 10:28:22.282056 2014] [:error] [pid 1138:tid 140421835532032] [remote 192.168.15.203:44679]   File "/var/www/testsite/testsite/wsgi.py", line 16, in <module>
[Wed Dec 31 10:28:22.282110 2014] [:error] [pid 1138:tid 140421835532032] [remote 192.168.15.203:44679]     application = get_wsgi_application()
[Wed Dec 31 10:28:22.282122 2014] [:error] [pid 1138:tid 140421835532032] [remote 192.168.15.203:44679]   File "/usr/local/lib/python2.7/dist-packages/django/core/wsgi.py", line 14, in get_wsgi_application
[Wed Dec 31 10:28:22.282150 2014] [:error] [pid 1138:tid 140421835532032] [remote 192.168.15.203:44679]     django.setup()
[Wed Dec 31 10:28:22.282163 2014] [:error] [pid 1138:tid 140421835532032] [remote 192.168.15.203:44679]   File "/usr/local/lib/python2.7/dist-packages/django/__init__.py", line 21, in setup
[Wed Dec 31 10:28:22.282187 2014] [:error] [pid 1138:tid 140421835532032] [remote 192.168.15.203:44679]     apps.populate(settings.INSTALLED_APPS)
[Wed Dec 31 10:28:22.282199 2014] [:error] [pid 1138:tid 140421835532032] [remote 192.168.15.203:44679]   File "/usr/local/lib/python2.7/dist-packages/django/apps/registry.py", line 78, in populate
[Wed Dec 31 10:28:22.282237 2014] [:error] [pid 1138:tid 140421835532032] [remote 192.168.15.203:44679]     raise RuntimeError("populate() isn't reentrant")
[Wed Dec 31 10:28:22.282255 2014] [:error] [pid 1138:tid 140421835532032] [remote 192.168.15.203:44679] RuntimeError: populate() isn't reentrant
[Wed Dec 31 10:43:07.306379 2014] [:error] [pid 1137:tid 140421827139328] [remote 192.168.15.203:45191] mod_wsgi (pid=1137): Target WSGI script '/var/www/testsite/testsite/wsgi.py' cannot be loaded as Python module.
[Wed Dec 31 10:43:07.306505 2014] [:error] [pid 1137:tid 140421827139328] [remote 192.168.15.203:45191] mod_wsgi (pid=1137): Exception occurred processing WSGI script '/var/www/testsite/testsite/wsgi.py'.
[Wed Dec 31 10:43:07.306526 2014] [:error] [pid 1137:tid 140421827139328] [remote 192.168.15.203:45191] Traceback (most recent call last):
[Wed Dec 31 10:43:07.306555 2014] [:error] [pid 1137:tid 140421827139328] [remote 192.168.15.203:45191]   File "/var/www/testsite/testsite/wsgi.py", line 16, in <module>
[Wed Dec 31 10:43:07.306586 2014] [:error] [pid 1137:tid 140421827139328] [remote 192.168.15.203:45191]     application = get_wsgi_application()
[Wed Dec 31 10:43:07.306598 2014] [:error] [pid 1137:tid 140421827139328] [remote 192.168.15.203:45191]   File "/usr/local/lib/python2.7/dist-packages/django/core/wsgi.py", line 14, in get_wsgi_application
[Wed Dec 31 10:43:07.306619 2014] [:error] [pid 1137:tid 140421827139328] [remote 192.168.15.203:45191]     django.setup()
[Wed Dec 31 10:43:07.306631 2014] [:error] [pid 1137:tid 140421827139328] [remote 192.168.15.203:45191]   File "/usr/local/lib/python2.7/dist-packages/django/__init__.py", line 21, in setup
[Wed Dec 31 10:43:07.306648 2014] [:error] [pid 1137:tid 140421827139328] [remote 192.168.15.203:45191]     apps.populate(settings.INSTALLED_APPS)
[Wed Dec 31 10:43:07.306659 2014] [:error] [pid 1137:tid 140421827139328] [remote 192.168.15.203:45191]   File "/usr/local/lib/python2.7/dist-packages/django/apps/registry.py", line 78, in populate
[Wed Dec 31 10:43:07.306677 2014] [:error] [pid 1137:tid 140421827139328] [remote 192.168.15.203:45191]     raise RuntimeError("populate() isn't reentrant")
[Wed Dec 31 10:43:07.306694 2014] [:error] [pid 1137:tid 140421827139328] [remote 192.168.15.203:45191] RuntimeError: populate() isn't reentrant
[Wed Dec 31 10:43:07.922641 2014] [:error] [pid 1138:tid 140421718034176] [remote 192.168.15.203:44679] mod_wsgi (pid=1138): Target WSGI script '/var/www/testsite/testsite/wsgi.py' cannot be loaded as Python module.
[Wed Dec 31 10:43:07.923538 2014] [:error] [pid 1138:tid 140421718034176] [remote 192.168.15.203:44679] mod_wsgi (pid=1138): Exception occurred processing WSGI script '/var/www/testsite/testsite/wsgi.py'.
[Wed Dec 31 10:43:07.923577 2014] [:error] [pid 1138:tid 140421718034176] [remote 192.168.15.203:44679] Traceback (most recent call last):
[Wed Dec 31 10:43:07.923623 2014] [:error] [pid 1138:tid 140421718034176] [remote 192.168.15.203:44679]   File "/var/www/testsite/testsite/wsgi.py", line 16, in <module>
[Wed Dec 31 10:43:07.923712 2014] [:error] [pid 1138:tid 140421718034176] [remote 192.168.15.203:44679]     application = get_wsgi_application()
[Wed Dec 31 10:43:07.923726 2014] [:error] [pid 1138:tid 140421718034176] [remote 192.168.15.203:44679]   File "/usr/local/lib/python2.7/dist-packages/django/core/wsgi.py", line 14, in get_wsgi_application
[Wed Dec 31 10:43:07.923755 2014] [:error] [pid 1138:tid 140421718034176] [remote 192.168.15.203:44679]     django.setup()
[Wed Dec 31 10:43:07.923768 2014] [:error] [pid 1138:tid 140421718034176] [remote 192.168.15.203:44679]   File "/usr/local/lib/python2.7/dist-packages/django/__init__.py", line 21, in setup
[Wed Dec 31 10:43:07.923787 2014] [:error] [pid 1138:tid 140421718034176] [remote 192.168.15.203:44679]     apps.populate(settings.INSTALLED_APPS)
[Wed Dec 31 10:43:07.923798 2014] [:error] [pid 1138:tid 140421718034176] [remote 192.168.15.203:44679]   File "/usr/local/lib/python2.7/dist-packages/django/apps/registry.py", line 78, in populate
[Wed Dec 31 10:43:07.923860 2014] [:error] [pid 1138:tid 140421718034176] [remote 192.168.15.203:44679]     raise RuntimeError("populate() isn't reentrant")
[Wed Dec 31 10:43:07.923880 2014] [:error] [pid 1138:tid 140421718034176] [remote 192.168.15.203:44679] RuntimeError: populate() isn't reentrant
[Wed Dec 31 10:53:18.852649 2014] [:error] [pid 1137:tid 140421718034176] [remote 192.168.15.203:45191] mod_wsgi (pid=1137): Target WSGI script '/var/www/testsite/testsite/wsgi.py' cannot be loaded as Python module.
[Wed Dec 31 10:53:18.852745 2014] [:error] [pid 1137:tid 140421718034176] [remote 192.168.15.203:45191] mod_wsgi (pid=1137): Exception occurred processing WSGI script '/var/www/testsite/testsite/wsgi.py'.
[Wed Dec 31 10:53:18.852785 2014] [:error] [pid 1137:tid 140421718034176] [remote 192.168.15.203:45191] Traceback (most recent call last):
[Wed Dec 31 10:53:18.852821 2014] [:error] [pid 1137:tid 140421718034176] [remote 192.168.15.203:45191]   File "/var/www/testsite/testsite/wsgi.py", line 16, in <module>
[Wed Dec 31 10:53:18.852902 2014] [:error] [pid 1137:tid 140421718034176] [remote 192.168.15.203:45191]     application = get_wsgi_application()
[Wed Dec 31 10:53:18.852914 2014] [:error] [pid 1137:tid 140421718034176] [remote 192.168.15.203:45191]   File "/usr/local/lib/python2.7/dist-packages/django/core/wsgi.py", line 14, in get_wsgi_application
[Wed Dec 31 10:53:18.852987 2014] [:error] [pid 1137:tid 140421718034176] [remote 192.168.15.203:45191]     django.setup()
[Wed Dec 31 10:53:18.852999 2014] [:error] [pid 1137:tid 140421718034176] [remote 192.168.15.203:45191]   File "/usr/local/lib/python2.7/dist-packages/django/__init__.py", line 21, in setup
[Wed Dec 31 10:53:18.853023 2014] [:error] [pid 1137:tid 140421718034176] [remote 192.168.15.203:45191]     apps.populate(settings.INSTALLED_APPS)
[Wed Dec 31 10:53:18.853035 2014] [:error] [pid 1137:tid 140421718034176] [remote 192.168.15.203:45191]   File "/usr/local/lib/python2.7/dist-packages/django/apps/registry.py", line 78, in populate
[Wed Dec 31 10:53:18.853079 2014] [:error] [pid 1137:tid 140421718034176] [remote 192.168.15.203:45191]     raise RuntimeError("populate() isn't reentrant")
[Wed Dec 31 10:53:18.853097 2014] [:error] [pid 1137:tid 140421718034176] [remote 192.168.15.203:45191] RuntimeError: populate() isn't reentrant
[Wed Dec 31 10:53:19.586023 2014] [:error] [pid 1138:tid 140421835532032] [remote 192.168.15.203:44679] mod_wsgi (pid=1138): Target WSGI script '/var/www/testsite/testsite/wsgi.py' cannot be loaded as Python module.
[Wed Dec 31 10:53:19.586363 2014] [:error] [pid 1138:tid 140421835532032] [remote 192.168.15.203:44679] mod_wsgi (pid=1138): Exception occurred processing WSGI script '/var/www/testsite/testsite/wsgi.py'.
[Wed Dec 31 10:53:19.586424 2014] [:error] [pid 1138:tid 140421835532032] [remote 192.168.15.203:44679] Traceback (most recent call last):
[Wed Dec 31 10:53:19.586469 2014] [:error] [pid 1138:tid 140421835532032] [remote 192.168.15.203:44679]   File "/var/www/testsite/testsite/wsgi.py", line 16, in <module>
[Wed Dec 31 10:53:19.586528 2014] [:error] [pid 1138:tid 140421835532032] [remote 192.168.15.203:44679]     application = get_wsgi_application()
[Wed Dec 31 10:53:19.586540 2014] [:error] [pid 1138:tid 140421835532032] [remote 192.168.15.203:44679]   File "/usr/local/lib/python2.7/dist-packages/django/core/wsgi.py", line 14, in get_wsgi_application
[Wed Dec 31 10:53:19.586568 2014] [:error] [pid 1138:tid 140421835532032] [remote 192.168.15.203:44679]     django.setup()
[Wed Dec 31 10:53:19.586581 2014] [:error] [pid 1138:tid 140421835532032] [remote 192.168.15.203:44679]   File "/usr/local/lib/python2.7/dist-packages/django/__init__.py", line 21, in setup
[Wed Dec 31 10:53:19.586605 2014] [:error] [pid 1138:tid 140421835532032] [remote 192.168.15.203:44679]     apps.populate(settings.INSTALLED_APPS)
[Wed Dec 31 10:53:19.586617 2014] [:error] [pid 1138:tid 140421835532032] [remote 192.168.15.203:44679]   File "/usr/local/lib/python2.7/dist-packages/django/apps/registry.py", line 78, in populate
[Wed Dec 31 10:53:19.586651 2014] [:error] [pid 1138:tid 140421835532032] [remote 192.168.15.203:44679]     raise RuntimeError("populate() isn't reentrant")
[Wed Dec 31 10:53:19.586669 2014] [:error] [pid 1138:tid 140421835532032] [remote 192.168.15.203:44679] RuntimeError: populate() isn't reentrant
[Wed Dec 31 10:53:38.131666 2014] [:error] [pid 1137:tid 140421827139328] [remote 192.168.15.203:45191] mod_wsgi (pid=1137): Target WSGI script '/var/www/testsite/testsite/wsgi.py' cannot be loaded as Python module.
[Wed Dec 31 10:53:38.131722 2014] [:error] [pid 1137:tid 140421827139328] [remote 192.168.15.203:45191] mod_wsgi (pid=1137): Exception occurred processing WSGI script '/var/www/testsite/testsite/wsgi.py'.
[Wed Dec 31 10:53:38.131749 2014] [:error] [pid 1137:tid 140421827139328] [remote 192.168.15.203:45191] Traceback (most recent call last):
[Wed Dec 31 10:53:38.131782 2014] [:error] [pid 1137:tid 140421827139328] [remote 192.168.15.203:45191]   File "/var/www/testsite/testsite/wsgi.py", line 16, in <module>
[Wed Dec 31 10:53:38.131819 2014] [:error] [pid 1137:tid 140421827139328] [remote 192.168.15.203:45191]     application = get_wsgi_application()
[Wed Dec 31 10:53:38.131830 2014] [:error] [pid 1137:tid 140421827139328] [remote 192.168.15.203:45191]   File "/usr/local/lib/python2.7/dist-packages/django/core/wsgi.py", line 14, in get_wsgi_application
[Wed Dec 31 10:53:38.131851 2014] [:error] [pid 1137:tid 140421827139328] [remote 192.168.15.203:45191]     django.setup()
[Wed Dec 31 10:53:38.131863 2014] [:error] [pid 1137:tid 140421827139328] [remote 192.168.15.203:45191]   File "/usr/local/lib/python2.7/dist-packages/django/__init__.py", line 21, in setup
[Wed Dec 31 10:53:38.131880 2014] [:error] [pid 1137:tid 140421827139328] [remote 192.168.15.203:45191]     apps.populate(settings.INSTALLED_APPS)
[Wed Dec 31 10:53:38.131891 2014] [:error] [pid 1137:tid 140421827139328] [remote 192.168.15.203:45191]   File "/usr/local/lib/python2.7/dist-packages/django/apps/registry.py", line 78, in populate
[Wed Dec 31 10:53:38.131909 2014] [:error] [pid 1137:tid 140421827139328] [remote 192.168.15.203:45191]     raise RuntimeError("populate() isn't reentrant")
[Wed Dec 31 10:53:38.131928 2014] [:error] [pid 1137:tid 140421827139328] [remote 192.168.15.203:45191] RuntimeError: populate() isn't reentrant
[Wed Dec 31 10:53:38.144326 2014] [:error] [pid 1138:tid 140421718034176] [remote 192.168.15.203:44679] mod_wsgi (pid=1138): Target WSGI script '/var/www/testsite/testsite/wsgi.py' cannot be loaded as Python module.
[Wed Dec 31 10:53:38.144358 2014] [:error] [pid 1138:tid 140421718034176] [remote 192.168.15.203:44679] mod_wsgi (pid=1138): Exception occurred processing WSGI script '/var/www/testsite/testsite/wsgi.py'.
[Wed Dec 31 10:53:38.144378 2014] [:error] [pid 1138:tid 140421718034176] [remote 192.168.15.203:44679] Traceback (most recent call last):
[Wed Dec 31 10:53:38.144423 2014] [:error] [pid 1138:tid 140421718034176] [remote 192.168.15.203:44679]   File "/var/www/testsite/testsite/wsgi.py", line 16, in <module>
[Wed Dec 31 10:53:38.144455 2014] [:error] [pid 1138:tid 140421718034176] [remote 192.168.15.203:44679]     application = get_wsgi_application()
[Wed Dec 31 10:53:38.144466 2014] [:error] [pid 1138:tid 140421718034176] [remote 192.168.15.203:44679]   File "/usr/local/lib/python2.7/dist-packages/django/core/wsgi.py", line 14, in get_wsgi_application
[Wed Dec 31 10:53:38.144488 2014] [:error] [pid 1138:tid 140421718034176] [remote 192.168.15.203:44679]     django.setup()
[Wed Dec 31 10:53:38.144499 2014] [:error] [pid 1138:tid 140421718034176] [remote 192.168.15.203:44679]   File "/usr/local/lib/python2.7/dist-packages/django/__init__.py", line 21, in setup
[Wed Dec 31 10:53:38.144516 2014] [:error] [pid 1138:tid 140421718034176] [remote 192.168.15.203:44679]     apps.populate(settings.INSTALLED_APPS)
[Wed Dec 31 10:53:38.144527 2014] [:error] [pid 1138:tid 140421718034176] [remote 192.168.15.203:44679]   File "/usr/local/lib/python2.7/dist-packages/django/apps/registry.py", line 78, in populate
[Wed Dec 31 10:53:38.144558 2014] [:error] [pid 1138:tid 140421718034176] [remote 192.168.15.203:44679]     raise RuntimeError("populate() isn't reentrant")
[Wed Dec 31 10:53:38.144576 2014] [:error] [pid 1138:tid 140421718034176] [remote 192.168.15.203:44679] RuntimeError: populate() isn't reentrant
[Wed Dec 31 10:53:40.578047 2014] [:error] [pid 1137:tid 140421718034176] [remote 192.168.15.203:45191] mod_wsgi (pid=1137): Target WSGI script '/var/www/testsite/testsite/wsgi.py' cannot be loaded as Python module.
[Wed Dec 31 10:53:40.578084 2014] [:error] [pid 1137:tid 140421718034176] [remote 192.168.15.203:45191] mod_wsgi (pid=1137): Exception occurred processing WSGI script '/var/www/testsite/testsite/wsgi.py'.
[Wed Dec 31 10:53:40.578105 2014] [:error] [pid 1137:tid 140421718034176] [remote 192.168.15.203:45191] Traceback (most recent call last):
[Wed Dec 31 10:53:40.578146 2014] [:error] [pid 1137:tid 140421718034176] [remote 192.168.15.203:45191]   File "/var/www/testsite/testsite/wsgi.py", line 16, in <module>
[Wed Dec 31 10:53:40.578178 2014] [:error] [pid 1137:tid 140421718034176] [remote 192.168.15.203:45191]     application = get_wsgi_application()
[Wed Dec 31 10:53:40.578189 2014] [:error] [pid 1137:tid 140421718034176] [remote 192.168.15.203:45191]   File "/usr/local/lib/python2.7/dist-packages/django/core/wsgi.py", line 14, in get_wsgi_application
[Wed Dec 31 10:53:40.578210 2014] [:error] [pid 1137:tid 140421718034176] [remote 192.168.15.203:45191]     django.setup()
[Wed Dec 31 10:53:40.578222 2014] [:error] [pid 1137:tid 140421718034176] [remote 192.168.15.203:45191]   File "/usr/local/lib/python2.7/dist-packages/django/__init__.py", line 21, in setup
[Wed Dec 31 10:53:40.578239 2014] [:error] [pid 1137:tid 140421718034176] [remote 192.168.15.203:45191]     apps.populate(settings.INSTALLED_APPS)
[Wed Dec 31 10:53:40.578250 2014] [:error] [pid 1137:tid 140421718034176] [remote 192.168.15.203:45191]   File "/usr/local/lib/python2.7/dist-packages/django/apps/registry.py", line 78, in populate
[Wed Dec 31 10:53:40.578267 2014] [:error] [pid 1137:tid 140421718034176] [remote 192.168.15.203:45191]     raise RuntimeError("populate() isn't reentrant")
[Wed Dec 31 10:53:40.578285 2014] [:error] [pid 1137:tid 140421718034176] [remote 192.168.15.203:45191] RuntimeError: populate() isn't reentrant
[Wed Dec 31 10:53:40.591395 2014] [:error] [pid 1138:tid 140421835532032] [remote 192.168.15.203:44679] mod_wsgi (pid=1138): Target WSGI script '/var/www/testsite/testsite/wsgi.py' cannot be loaded as Python module.
[Wed Dec 31 10:53:40.591435 2014] [:error] [pid 1138:tid 140421835532032] [remote 192.168.15.203:44679] mod_wsgi (pid=1138): Exception occurred processing WSGI script '/var/www/testsite/testsite/wsgi.py'.
[Wed Dec 31 10:53:40.591459 2014] [:error] [pid 1138:tid 140421835532032] [remote 192.168.15.203:44679] Traceback (most recent call last):
[Wed Dec 31 10:53:40.591483 2014] [:error] [pid 1138:tid 140421835532032] [remote 192.168.15.203:44679]   File "/var/www/testsite/testsite/wsgi.py", line 16, in <module>
[Wed Dec 31 10:53:40.591523 2014] [:error] [pid 1138:tid 140421835532032] [remote 192.168.15.203:44679]     application = get_wsgi_application()
[Wed Dec 31 10:53:40.591534 2014] [:error] [pid 1138:tid 140421835532032] [remote 192.168.15.203:44679]   File "/usr/local/lib/python2.7/dist-packages/django/core/wsgi.py", line 14, in get_wsgi_application
[Wed Dec 31 10:53:40.591558 2014] [:error] [pid 1138:tid 140421835532032] [remote 192.168.15.203:44679]     django.setup()
[Wed Dec 31 10:53:40.591570 2014] [:error] [pid 1138:tid 140421835532032] [remote 192.168.15.203:44679]   File "/usr/local/lib/python2.7/dist-packages/django/__init__.py", line 21, in setup
[Wed Dec 31 10:53:40.591588 2014] [:error] [pid 1138:tid 140421835532032] [remote 192.168.15.203:44679]     apps.populate(settings.INSTALLED_APPS)
[Wed Dec 31 10:53:40.591599 2014] [:error] [pid 1138:tid 140421835532032] [remote 192.168.15.203:44679]   File "/usr/local/lib/python2.7/dist-packages/django/apps/registry.py", line 78, in populate
[Wed Dec 31 10:53:40.591652 2014] [:error] [pid 1138:tid 140421835532032] [remote 192.168.15.203:44679]     raise RuntimeError("populate() isn't reentrant")
[Wed Dec 31 10:53:40.591671 2014] [:error] [pid 1138:tid 140421835532032] [remote 192.168.15.203:44679] RuntimeError: populate() isn't reentrant
[Wed Dec 31 10:53:41.903337 2014] [:error] [pid 1138:tid 140421718034176] [remote 192.168.15.203:46215] mod_wsgi (pid=1138): Target WSGI script '/var/www/testsite/testsite/wsgi.py' cannot be loaded as Python module.
[Wed Dec 31 10:53:41.903370 2014] [:error] [pid 1138:tid 140421718034176] [remote 192.168.15.203:46215] mod_wsgi (pid=1138): Exception occurred processing WSGI script '/var/www/testsite/testsite/wsgi.py'.
[Wed Dec 31 10:53:41.903392 2014] [:error] [pid 1138:tid 140421718034176] [remote 192.168.15.203:46215] Traceback (most recent call last):
[Wed Dec 31 10:53:41.903414 2014] [:error] [pid 1138:tid 140421718034176] [remote 192.168.15.203:46215]   File "/var/www/testsite/testsite/wsgi.py", line 16, in <module>
[Wed Dec 31 10:53:41.903448 2014] [:error] [pid 1138:tid 140421718034176] [remote 192.168.15.203:46215]     application = get_wsgi_application()
[Wed Dec 31 10:53:41.903459 2014] [:error] [pid 1138:tid 140421718034176] [remote 192.168.15.203:46215]   File "/usr/local/lib/python2.7/dist-packages/django/core/wsgi.py", line 14, in get_wsgi_application
[Wed Dec 31 10:53:41.903480 2014] [:error] [pid 1138:tid 140421718034176] [remote 192.168.15.203:46215]     django.setup()
[Wed Dec 31 10:53:41.903492 2014] [:error] [pid 1138:tid 140421718034176] [remote 192.168.15.203:46215]   File "/usr/local/lib/python2.7/dist-packages/django/__init__.py", line 21, in setup
[Wed Dec 31 10:53:41.903509 2014] [:error] [pid 1138:tid 140421718034176] [remote 192.168.15.203:46215]     apps.populate(settings.INSTALLED_APPS)
[Wed Dec 31 10:53:41.903520 2014] [:error] [pid 1138:tid 140421718034176] [remote 192.168.15.203:46215]   File "/usr/local/lib/python2.7/dist-packages/django/apps/registry.py", line 78, in populate
[Wed Dec 31 10:53:41.903538 2014] [:error] [pid 1138:tid 140421718034176] [remote 192.168.15.203:46215]     raise RuntimeError("populate() isn't reentrant")
[Wed Dec 31 10:53:41.903556 2014] [:error] [pid 1138:tid 140421718034176] [remote 192.168.15.203:46215] RuntimeError: populate() isn't reentrant
[Wed Dec 31 10:53:41.913960 2014] [:error] [pid 1137:tid 140421827139328] [remote 192.168.15.203:45191] mod_wsgi (pid=1137): Target WSGI script '/var/www/testsite/testsite/wsgi.py' cannot be loaded as Python module.
[Wed Dec 31 10:53:41.913998 2014] [:error] [pid 1137:tid 140421827139328] [remote 192.168.15.203:45191] mod_wsgi (pid=1137): Exception occurred processing WSGI script '/var/www/testsite/testsite/wsgi.py'.
[Wed Dec 31 10:53:41.914021 2014] [:error] [pid 1137:tid 140421827139328] [remote 192.168.15.203:45191] Traceback (most recent call last):
[Wed Dec 31 10:53:41.914046 2014] [:error] [pid 1137:tid 140421827139328] [remote 192.168.15.203:45191]   File "/var/www/testsite/testsite/wsgi.py", line 16, in <module>
[Wed Dec 31 10:53:41.914095 2014] [:error] [pid 1137:tid 140421827139328] [remote 192.168.15.203:45191]     application = get_wsgi_application()
[Wed Dec 31 10:53:41.914107 2014] [:error] [pid 1137:tid 140421827139328] [remote 192.168.15.203:45191]   File "/usr/local/lib/python2.7/dist-packages/django/core/wsgi.py", line 14, in get_wsgi_application
[Wed Dec 31 10:53:41.914130 2014] [:error] [pid 1137:tid 140421827139328] [remote 192.168.15.203:45191]     django.setup()
[Wed Dec 31 10:53:41.914142 2014] [:error] [pid 1137:tid 140421827139328] [remote 192.168.15.203:45191]   File "/usr/local/lib/python2.7/dist-packages/django/__init__.py", line 21, in setup
[Wed Dec 31 10:53:41.914159 2014] [:error] [pid 1137:tid 140421827139328] [remote 192.168.15.203:45191]     apps.populate(settings.INSTALLED_APPS)
[Wed Dec 31 10:53:41.914170 2014] [:error] [pid 1137:tid 140421827139328] [remote 192.168.15.203:45191]   File "/usr/local/lib/python2.7/dist-packages/django/apps/registry.py", line 78, in populate
[Wed Dec 31 10:53:41.914205 2014] [:error] [pid 1137:tid 140421827139328] [remote 192.168.15.203:45191]     raise RuntimeError("populate() isn't reentrant")
[Wed Dec 31 10:53:41.914225 2014] [:error] [pid 1137:tid 140421827139328] [remote 192.168.15.203:45191] RuntimeError: populate() isn't reentrant
[Wed Dec 31 10:53:42.255005 2014] [:error] [pid 1137:tid 140421718034176] [remote 192.168.15.203:44679] mod_wsgi (pid=1137): Target WSGI script '/var/www/testsite/testsite/wsgi.py' cannot be loaded as Python module.
[Wed Dec 31 10:53:42.255037 2014] [:error] [pid 1137:tid 140421718034176] [remote 192.168.15.203:44679] mod_wsgi (pid=1137): Exception occurred processing WSGI script '/var/www/testsite/testsite/wsgi.py'.
[Wed Dec 31 10:53:42.255059 2014] [:error] [pid 1137:tid 140421718034176] [remote 192.168.15.203:44679] Traceback (most recent call last):
[Wed Dec 31 10:53:42.255081 2014] [:error] [pid 1137:tid 140421718034176] [remote 192.168.15.203:44679]   File "/var/www/testsite/testsite/wsgi.py", line 16, in <module>
[Wed Dec 31 10:53:42.255127 2014] [:error] [pid 1137:tid 140421718034176] [remote 192.168.15.203:44679]     application = get_wsgi_application()
[Wed Dec 31 10:53:42.255140 2014] [:error] [pid 1137:tid 140421718034176] [remote 192.168.15.203:44679]   File "/usr/local/lib/python2.7/dist-packages/django/core/wsgi.py", line 14, in get_wsgi_application
[Wed Dec 31 10:53:42.255161 2014] [:error] [pid 1137:tid 140421718034176] [remote 192.168.15.203:44679]     django.setup()
[Wed Dec 31 10:53:42.255173 2014] [:error] [pid 1137:tid 140421718034176] [remote 192.168.15.203:44679]   File "/usr/local/lib/python2.7/dist-packages/django/__init__.py", line 21, in setup
[Wed Dec 31 10:53:42.255190 2014] [:error] [pid 1137:tid 140421718034176] [remote 192.168.15.203:44679]     apps.populate(settings.INSTALLED_APPS)
[Wed Dec 31 10:53:42.255201 2014] [:error] [pid 1137:tid 140421718034176] [remote 192.168.15.203:44679]   File "/usr/local/lib/python2.7/dist-packages/django/apps/registry.py", line 78, in populate
[Wed Dec 31 10:53:42.255219 2014] [:error] [pid 1137:tid 140421718034176] [remote 192.168.15.203:44679]     raise RuntimeError("populate() isn't reentrant")
[Wed Dec 31 10:53:42.255236 2014] [:error] [pid 1137:tid 140421718034176] [remote 192.168.15.203:44679] RuntimeError: populate() isn't reentrant
[Wed Dec 31 10:53:42.267484 2014] [:error] [pid 1138:tid 140421835532032] [remote 192.168.15.203:46215] mod_wsgi (pid=1138): Target WSGI script '/var/www/testsite/testsite/wsgi.py' cannot be loaded as Python module.
[Wed Dec 31 10:53:42.267524 2014] [:error] [pid 1138:tid 140421835532032] [remote 192.168.15.203:46215] mod_wsgi (pid=1138): Exception occurred processing WSGI script '/var/www/testsite/testsite/wsgi.py'.
[Wed Dec 31 10:53:42.267546 2014] [:error] [pid 1138:tid 140421835532032] [remote 192.168.15.203:46215] Traceback (most recent call last):
[Wed Dec 31 10:53:42.267572 2014] [:error] [pid 1138:tid 140421835532032] [remote 192.168.15.203:46215]   File "/var/www/testsite/testsite/wsgi.py", line 16, in <module>
[Wed Dec 31 10:53:42.268297 2014] [:error] [pid 1138:tid 140421835532032] [remote 192.168.15.203:46215]     application = get_wsgi_application()
[Wed Dec 31 10:53:42.268315 2014] [:error] [pid 1138:tid 140421835532032] [remote 192.168.15.203:46215]   File "/usr/local/lib/python2.7/dist-packages/django/core/wsgi.py", line 14, in get_wsgi_application
[Wed Dec 31 10:53:42.268337 2014] [:error] [pid 1138:tid 140421835532032] [remote 192.168.15.203:46215]     django.setup()
[Wed Dec 31 10:53:42.268348 2014] [:error] [pid 1138:tid 140421835532032] [remote 192.168.15.203:46215]   File "/usr/local/lib/python2.7/dist-packages/django/__init__.py", line 21, in setup
[Wed Dec 31 10:53:42.268365 2014] [:error] [pid 1138:tid 140421835532032] [remote 192.168.15.203:46215]     apps.populate(settings.INSTALLED_APPS)
[Wed Dec 31 10:53:42.268390 2014] [:error] [pid 1138:tid 140421835532032] [remote 192.168.15.203:46215]   File "/usr/local/lib/python2.7/dist-packages/django/apps/registry.py", line 78, in populate
[Wed Dec 31 10:53:42.268426 2014] [:error] [pid 1138:tid 140421835532032] [remote 192.168.15.203:46215]     raise RuntimeError("populate() isn't reentrant")
[Wed Dec 31 10:53:42.268445 2014] [:error] [pid 1138:tid 140421835532032] [remote 192.168.15.203:46215] RuntimeError: populate() isn't reentrant
[Wed Dec 31 10:53:42.439864 2014] [:error] [pid 1138:tid 140421718034176] [remote 192.168.15.203:44935] mod_wsgi (pid=1138): Target WSGI script '/var/www/testsite/testsite/wsgi.py' cannot be loaded as Python module.
[Wed Dec 31 10:53:42.439892 2014] [:error] [pid 1138:tid 140421718034176] [remote 192.168.15.203:44935] mod_wsgi (pid=1138): Exception occurred processing WSGI script '/var/www/testsite/testsite/wsgi.py'.
[Wed Dec 31 10:53:42.439914 2014] [:error] [pid 1138:tid 140421718034176] [remote 192.168.15.203:44935] Traceback (most recent call last):
[Wed Dec 31 10:53:42.439937 2014] [:error] [pid 1138:tid 140421718034176] [remote 192.168.15.203:44935]   File "/var/www/testsite/testsite/wsgi.py", line 16, in <module>
[Wed Dec 31 10:53:42.439968 2014] [:error] [pid 1138:tid 140421718034176] [remote 192.168.15.203:44935]     application = get_wsgi_application()
[Wed Dec 31 10:53:42.439979 2014] [:error] [pid 1138:tid 140421718034176] [remote 192.168.15.203:44935]   File "/usr/local/lib/python2.7/dist-packages/django/core/wsgi.py", line 14, in get_wsgi_application
[Wed Dec 31 10:53:42.440001 2014] [:error] [pid 1138:tid 140421718034176] [remote 192.168.15.203:44935]     django.setup()
[Wed Dec 31 10:53:42.440012 2014] [:error] [pid 1138:tid 140421718034176] [remote 192.168.15.203:44935]   File "/usr/local/lib/python2.7/dist-packages/django/__init__.py", line 21, in setup
[Wed Dec 31 10:53:42.440029 2014] [:error] [pid 1138:tid 140421718034176] [remote 192.168.15.203:44935]     apps.populate(settings.INSTALLED_APPS)
[Wed Dec 31 10:53:42.440040 2014] [:error] [pid 1138:tid 140421718034176] [remote 192.168.15.203:44935]   File "/usr/local/lib/python2.7/dist-packages/django/apps/registry.py", line 78, in populate
[Wed Dec 31 10:53:42.440057 2014] [:error] [pid 1138:tid 140421718034176] [remote 192.168.15.203:44935]     raise RuntimeError("populate() isn't reentrant")
[Wed Dec 31 10:53:42.440074 2014] [:error] [pid 1138:tid 140421718034176] [remote 192.168.15.203:44935] RuntimeError: populate() isn't reentrant
[Wed Dec 31 10:53:42.452262 2014] [:error] [pid 1137:tid 140421827139328] [remote 192.168.15.203:44679] mod_wsgi (pid=1137): Target WSGI script '/var/www/testsite/testsite/wsgi.py' cannot be loaded as Python module.
[Wed Dec 31 10:53:42.452292 2014] [:error] [pid 1137:tid 140421827139328] [remote 192.168.15.203:44679] mod_wsgi (pid=1137): Exception occurred processing WSGI script '/var/www/testsite/testsite/wsgi.py'.
[Wed Dec 31 10:53:42.452312 2014] [:error] [pid 1137:tid 140421827139328] [remote 192.168.15.203:44679] Traceback (most recent call last):
[Wed Dec 31 10:53:42.452335 2014] [:error] [pid 1137:tid 140421827139328] [remote 192.168.15.203:44679]   File "/var/www/testsite/testsite/wsgi.py", line 16, in <module>
[Wed Dec 31 10:53:42.453134 2014] [:error] [pid 1137:tid 140421827139328] [remote 192.168.15.203:44679]     application = get_wsgi_application()
[Wed Dec 31 10:53:42.453147 2014] [:error] [pid 1137:tid 140421827139328] [remote 192.168.15.203:44679]   File "/usr/local/lib/python2.7/dist-packages/django/core/wsgi.py", line 14, in get_wsgi_application
[Wed Dec 31 10:53:42.453168 2014] [:error] [pid 1137:tid 140421827139328] [remote 192.168.15.203:44679]     django.setup()
[Wed Dec 31 10:53:42.453179 2014] [:error] [pid 1137:tid 140421827139328] [remote 192.168.15.203:44679]   File "/usr/local/lib/python2.7/dist-packages/django/__init__.py", line 21, in setup
[Wed Dec 31 10:53:42.453196 2014] [:error] [pid 1137:tid 140421827139328] [remote 192.168.15.203:44679]     apps.populate(settings.INSTALLED_APPS)
[Wed Dec 31 10:53:42.453207 2014] [:error] [pid 1137:tid 140421827139328] [remote 192.168.15.203:44679]   File "/usr/local/lib/python2.7/dist-packages/django/apps/registry.py", line 78, in populate
[Wed Dec 31 10:53:42.453224 2014] [:error] [pid 1137:tid 140421827139328] [remote 192.168.15.203:44679]     raise RuntimeError("populate() isn't reentrant")
[Wed Dec 31 10:53:42.453253 2014] [:error] [pid 1137:tid 140421827139328] [remote 192.168.15.203:44679] RuntimeError: populate() isn't reentrant
[Wed Dec 31 10:53:42.631864 2014] [:error] [pid 1137:tid 140421718034176] [remote 192.168.15.203:44935] mod_wsgi (pid=1137): Target WSGI script '/var/www/testsite/testsite/wsgi.py' cannot be loaded as Python module.
[Wed Dec 31 10:53:42.631893 2014] [:error] [pid 1137:tid 140421718034176] [remote 192.168.15.203:44935] mod_wsgi (pid=1137): Exception occurred processing WSGI script '/var/www/testsite/testsite/wsgi.py'.
[Wed Dec 31 10:53:42.632061 2014] [:error] [pid 1137:tid 140421718034176] [remote 192.168.15.203:44935] Traceback (most recent call last):
[Wed Dec 31 10:53:42.632082 2014] [:error] [pid 1137:tid 140421718034176] [remote 192.168.15.203:44935]   File "/var/www/testsite/testsite/wsgi.py", line 16, in <module>
[Wed Dec 31 10:53:42.632112 2014] [:error] [pid 1137:tid 140421718034176] [remote 192.168.15.203:44935]     application = get_wsgi_application()
[Wed Dec 31 10:53:42.632124 2014] [:error] [pid 1137:tid 140421718034176] [remote 192.168.15.203:44935]   File "/usr/local/lib/python2.7/dist-packages/django/core/wsgi.py", line 14, in get_wsgi_application
[Wed Dec 31 10:53:42.632144 2014] [:error] [pid 1137:tid 140421718034176] [remote 192.168.15.203:44935]     django.setup()
[Wed Dec 31 10:53:42.632155 2014] [:error] [pid 1137:tid 140421718034176] [remote 192.168.15.203:44935]   File "/usr/local/lib/python2.7/dist-packages/django/__init__.py", line 21, in setup
[Wed Dec 31 10:53:42.632172 2014] [:error] [pid 1137:tid 140421718034176] [remote 192.168.15.203:44935]     apps.populate(settings.INSTALLED_APPS)
[Wed Dec 31 10:53:42.632183 2014] [:error] [pid 1137:tid 140421718034176] [remote 192.168.15.203:44935]   File "/usr/local/lib/python2.7/dist-packages/django/apps/registry.py", line 78, in populate
[Wed Dec 31 10:53:42.632201 2014] [:error] [pid 1137:tid 140421718034176] [remote 192.168.15.203:44935]     raise RuntimeError("populate() isn't reentrant")
[Wed Dec 31 10:53:42.632220 2014] [:error] [pid 1137:tid 140421718034176] [remote 192.168.15.203:44935] RuntimeError: populate() isn't reentrant
[Wed Dec 31 10:53:42.643468 2014] [:error] [pid 1138:tid 140421835532032] [remote 192.168.15.203:44935] mod_wsgi (pid=1138): Target WSGI script '/var/www/testsite/testsite/wsgi.py' cannot be loaded as Python module.
[Wed Dec 31 10:53:42.643512 2014] [:error] [pid 1138:tid 140421835532032] [remote 192.168.15.203:44935] mod_wsgi (pid=1138): Exception occurred processing WSGI script '/var/www/testsite/testsite/wsgi.py'.
[Wed Dec 31 10:53:42.643534 2014] [:error] [pid 1138:tid 140421835532032] [remote 192.168.15.203:44935] Traceback (most recent call last):
[Wed Dec 31 10:53:42.643562 2014] [:error] [pid 1138:tid 140421835532032] [remote 192.168.15.203:44935]   File "/var/www/testsite/testsite/wsgi.py", line 16, in <module>
[Wed Dec 31 10:53:42.643593 2014] [:error] [pid 1138:tid 140421835532032] [remote 192.168.15.203:44935]     application = get_wsgi_application()
[Wed Dec 31 10:53:42.643604 2014] [:error] [pid 1138:tid 140421835532032] [remote 192.168.15.203:44935]   File "/usr/local/lib/python2.7/dist-packages/django/core/wsgi.py", line 14, in get_wsgi_application
[Wed Dec 31 10:53:42.643626 2014] [:error] [pid 1138:tid 140421835532032] [remote 192.168.15.203:44935]     django.setup()
[Wed Dec 31 10:53:42.643638 2014] [:error] [pid 1138:tid 140421835532032] [remote 192.168.15.203:44935]   File "/usr/local/lib/python2.7/dist-packages/django/__init__.py", line 21, in setup
[Wed Dec 31 10:53:42.643655 2014] [:error] [pid 1138:tid 140421835532032] [remote 192.168.15.203:44935]     apps.populate(settings.INSTALLED_APPS)
[Wed Dec 31 10:53:42.643666 2014] [:error] [pid 1138:tid 140421835532032] [remote 192.168.15.203:44935]   File "/usr/local/lib/python2.7/dist-packages/django/apps/registry.py", line 78, in populate
[Wed Dec 31 10:53:42.643683 2014] [:error] [pid 1138:tid 140421835532032] [remote 192.168.15.203:44935]     raise RuntimeError("populate() isn't reentrant")
[Wed Dec 31 10:53:42.643716 2014] [:error] [pid 1138:tid 140421835532032] [remote 192.168.15.203:44935] RuntimeError: populate() isn't reentrant
[Wed Dec 31 10:56:26.740085 2014] [:error] [pid 1138:tid 140421718034176] [remote 192.168.15.203:44679] mod_wsgi (pid=1138): Target WSGI script '/var/www/testsite/testsite/wsgi.py' cannot be loaded as Python module.
[Wed Dec 31 10:56:26.740167 2014] [:error] [pid 1138:tid 140421718034176] [remote 192.168.15.203:44679] mod_wsgi (pid=1138): Exception occurred processing WSGI script '/var/www/testsite/testsite/wsgi.py'.
[Wed Dec 31 10:56:26.740207 2014] [:error] [pid 1138:tid 140421718034176] [remote 192.168.15.203:44679] Traceback (most recent call last):
[Wed Dec 31 10:56:26.740244 2014] [:error] [pid 1138:tid 140421718034176] [remote 192.168.15.203:44679]   File "/var/www/testsite/testsite/wsgi.py", line 16, in <module>
[Wed Dec 31 10:56:26.740315 2014] [:error] [pid 1138:tid 140421718034176] [remote 192.168.15.203:44679]     application = get_wsgi_application()
[Wed Dec 31 10:56:26.740328 2014] [:error] [pid 1138:tid 140421718034176] [remote 192.168.15.203:44679]   File "/usr/local/lib/python2.7/dist-packages/django/core/wsgi.py", line 14, in get_wsgi_application
[Wed Dec 31 10:56:26.740356 2014] [:error] [pid 1138:tid 140421718034176] [remote 192.168.15.203:44679]     django.setup()
[Wed Dec 31 10:56:26.740368 2014] [:error] [pid 1138:tid 140421718034176] [remote 192.168.15.203:44679]   File "/usr/local/lib/python2.7/dist-packages/django/__init__.py", line 21, in setup
[Wed Dec 31 10:56:26.740393 2014] [:error] [pid 1138:tid 140421718034176] [remote 192.168.15.203:44679]     apps.populate(settings.INSTALLED_APPS)
[Wed Dec 31 10:56:26.740404 2014] [:error] [pid 1138:tid 140421718034176] [remote 192.168.15.203:44679]   File "/usr/local/lib/python2.7/dist-packages/django/apps/registry.py", line 78, in populate
[Wed Dec 31 10:56:26.740430 2014] [:error] [pid 1138:tid 140421718034176] [remote 192.168.15.203:44679]     raise RuntimeError("populate() isn't reentrant")
[Wed Dec 31 10:56:26.740431 2014] [:error] [pid 1138:tid 140421718034176] [remote 192.168.15.203:44679] RuntimeError: populate() isn't reentrant
[Wed Dec 31 10:56:26.753794 2014] [:error] [pid 1137:tid 140421827139328] [remote 192.168.15.203:44935] mod_wsgi (pid=1137): Target WSGI script '/var/www/testsite/testsite/wsgi.py' cannot be loaded as Python module.
[Wed Dec 31 10:56:26.753866 2014] [:error] [pid 1137:tid 140421827139328] [remote 192.168.15.203:44935] mod_wsgi (pid=1137): Exception occurred processing WSGI script '/var/www/testsite/testsite/wsgi.py'.
[Wed Dec 31 10:56:26.753912 2014] [:error] [pid 1137:tid 140421827139328] [remote 192.168.15.203:44935] Traceback (most recent call last):
[Wed Dec 31 10:56:26.753958 2014] [:error] [pid 1137:tid 140421827139328] [remote 192.168.15.203:44935]   File "/var/www/testsite/testsite/wsgi.py", line 16, in <module>
[Wed Dec 31 10:56:26.754018 2014] [:error] [pid 1137:tid 140421827139328] [remote 192.168.15.203:44935]     application = get_wsgi_application()
[Wed Dec 31 10:56:26.754031 2014] [:error] [pid 1137:tid 140421827139328] [remote 192.168.15.203:44935]   File "/usr/local/lib/python2.7/dist-packages/django/core/wsgi.py", line 14, in get_wsgi_application
[Wed Dec 31 10:56:26.754060 2014] [:error] [pid 1137:tid 140421827139328] [remote 192.168.15.203:44935]     django.setup()
[Wed Dec 31 10:56:26.754072 2014] [:error] [pid 1137:tid 140421827139328] [remote 192.168.15.203:44935]   File "/usr/local/lib/python2.7/dist-packages/django/__init__.py", line 21, in setup
[Wed Dec 31 10:56:26.754098 2014] [:error] [pid 1137:tid 140421827139328] [remote 192.168.15.203:44935]     apps.populate(settings.INSTALLED_APPS)
[Wed Dec 31 10:56:26.754109 2014] [:error] [pid 1137:tid 140421827139328] [remote 192.168.15.203:44935]   File "/usr/local/lib/python2.7/dist-packages/django/apps/registry.py", line 78, in populate
[Wed Dec 31 10:56:26.754135 2014] [:error] [pid 1137:tid 140421827139328] [remote 192.168.15.203:44935]     raise RuntimeError("populate() isn't reentrant")
[Wed Dec 31 10:56:26.754172 2014] [:error] [pid 1137:tid 140421827139328] [remote 192.168.15.203:44935] RuntimeError: populate() isn't reentrant
[Wed Dec 31 10:56:27.247301 2014] [:error] [pid 1138:tid 140421835532032] [remote 192.168.15.203:44679] mod_wsgi (pid=1138): Target WSGI script '/var/www/testsite/testsite/wsgi.py' cannot be loaded as Python module.
[Wed Dec 31 10:56:27.247341 2014] [:error] [pid 1138:tid 140421835532032] [remote 192.168.15.203:44679] mod_wsgi (pid=1138): Exception occurred processing WSGI script '/var/www/testsite/testsite/wsgi.py'.
[Wed Dec 31 10:56:27.247368 2014] [:error] [pid 1138:tid 140421835532032] [remote 192.168.15.203:44679] Traceback (most recent call last):
[Wed Dec 31 10:56:27.247397 2014] [:error] [pid 1138:tid 140421835532032] [remote 192.168.15.203:44679]   File "/var/www/testsite/testsite/wsgi.py", line 16, in <module>
[Wed Dec 31 10:56:27.247427 2014] [:error] [pid 1138:tid 140421835532032] [remote 192.168.15.203:44679]     application = get_wsgi_application()
[Wed Dec 31 10:56:27.247438 2014] [:error] [pid 1138:tid 140421835532032] [remote 192.168.15.203:44679]   File "/usr/local/lib/python2.7/dist-packages/django/core/wsgi.py", line 14, in get_wsgi_application
[Wed Dec 31 10:56:27.247458 2014] [:error] [pid 1138:tid 140421835532032] [remote 192.168.15.203:44679]     django.setup()
[Wed Dec 31 10:56:27.247470 2014] [:error] [pid 1138:tid 140421835532032] [remote 192.168.15.203:44679]   File "/usr/local/lib/python2.7/dist-packages/django/__init__.py", line 21, in setup
[Wed Dec 31 10:56:27.247487 2014] [:error] [pid 1138:tid 140421835532032] [remote 192.168.15.203:44679]     apps.populate(settings.INSTALLED_APPS)
[Wed Dec 31 10:56:27.247498 2014] [:error] [pid 1138:tid 140421835532032] [remote 192.168.15.203:44679]   File "/usr/local/lib/python2.7/dist-packages/django/apps/registry.py", line 78, in populate
[Wed Dec 31 10:56:27.247516 2014] [:error] [pid 1138:tid 140421835532032] [remote 192.168.15.203:44679]     raise RuntimeError("populate() isn't reentrant")
[Wed Dec 31 10:56:27.247535 2014] [:error] [pid 1138:tid 140421835532032] [remote 192.168.15.203:44679] RuntimeError: populate() isn't reentrant
[Wed Dec 31 10:56:27.259341 2014] [:error] [pid 1137:tid 140421718034176] [remote 192.168.15.203:44935] mod_wsgi (pid=1137): Target WSGI script '/var/www/testsite/testsite/wsgi.py' cannot be loaded as Python module.
[Wed Dec 31 10:56:27.259370 2014] [:error] [pid 1137:tid 140421718034176] [remote 192.168.15.203:44935] mod_wsgi (pid=1137): Exception occurred processing WSGI script '/var/www/testsite/testsite/wsgi.py'.
[Wed Dec 31 10:56:27.259390 2014] [:error] [pid 1137:tid 140421718034176] [remote 192.168.15.203:44935] Traceback (most recent call last):
[Wed Dec 31 10:56:27.259413 2014] [:error] [pid 1137:tid 140421718034176] [remote 192.168.15.203:44935]   File "/var/www/testsite/testsite/wsgi.py", line 16, in <module>
[Wed Dec 31 10:56:27.259444 2014] [:error] [pid 1137:tid 140421718034176] [remote 192.168.15.203:44935]     application = get_wsgi_application()
[Wed Dec 31 10:56:27.259455 2014] [:error] [pid 1137:tid 140421718034176] [remote 192.168.15.203:44935]   File "/usr/local/lib/python2.7/dist-packages/django/core/wsgi.py", line 14, in get_wsgi_application
[Wed Dec 31 10:56:27.259475 2014] [:error] [pid 1137:tid 140421718034176] [remote 192.168.15.203:44935]     django.setup()
[Wed Dec 31 10:56:27.259487 2014] [:error] [pid 1137:tid 140421718034176] [remote 192.168.15.203:44935]   File "/usr/local/lib/python2.7/dist-packages/django/__init__.py", line 21, in setup
[Wed Dec 31 10:56:27.259504 2014] [:error] [pid 1137:tid 140421718034176] [remote 192.168.15.203:44935]     apps.populate(settings.INSTALLED_APPS)
[Wed Dec 31 10:56:27.259514 2014] [:error] [pid 1137:tid 140421718034176] [remote 192.168.15.203:44935]   File "/usr/local/lib/python2.7/dist-packages/django/apps/registry.py", line 78, in populate
[Wed Dec 31 10:56:27.259532 2014] [:error] [pid 1137:tid 140421718034176] [remote 192.168.15.203:44935]     raise RuntimeError("populate() isn't reentrant")
[Wed Dec 31 10:56:27.259561 2014] [:error] [pid 1137:tid 140421718034176] [remote 192.168.15.203:44935] RuntimeError: populate() isn't reentrant
[Wed Dec 31 10:56:27.455831 2014] [:error] [pid 1138:tid 140421718034176] [remote 192.168.15.203:44679] mod_wsgi (pid=1138): Target WSGI script '/var/www/testsite/testsite/wsgi.py' cannot be loaded as Python module.
[Wed Dec 31 10:56:27.455872 2014] [:error] [pid 1138:tid 140421718034176] [remote 192.168.15.203:44679] mod_wsgi (pid=1138): Exception occurred processing WSGI script '/var/www/testsite/testsite/wsgi.py'.
[Wed Dec 31 10:56:27.455896 2014] [:error] [pid 1138:tid 140421718034176] [remote 192.168.15.203:44679] Traceback (most recent call last):
[Wed Dec 31 10:56:27.455924 2014] [:error] [pid 1138:tid 140421718034176] [remote 192.168.15.203:44679]   File "/var/www/testsite/testsite/wsgi.py", line 16, in <module>
[Wed Dec 31 10:56:27.455963 2014] [:error] [pid 1138:tid 140421718034176] [remote 192.168.15.203:44679]     application = get_wsgi_application()
[Wed Dec 31 10:56:27.455974 2014] [:error] [pid 1138:tid 140421718034176] [remote 192.168.15.203:44679]   File "/usr/local/lib/python2.7/dist-packages/django/core/wsgi.py", line 14, in get_wsgi_application
[Wed Dec 31 10:56:27.455996 2014] [:error] [pid 1138:tid 140421718034176] [remote 192.168.15.203:44679]     django.setup()
[Wed Dec 31 10:56:27.456007 2014] [:error] [pid 1138:tid 140421718034176] [remote 192.168.15.203:44679]   File "/usr/local/lib/python2.7/dist-packages/django/__init__.py", line 21, in setup
[Wed Dec 31 10:56:27.456025 2014] [:error] [pid 1138:tid 140421718034176] [remote 192.168.15.203:44679]     apps.populate(settings.INSTALLED_APPS)
[Wed Dec 31 10:56:27.456035 2014] [:error] [pid 1138:tid 140421718034176] [remote 192.168.15.203:44679]   File "/usr/local/lib/python2.7/dist-packages/django/apps/registry.py", line 78, in populate
[Wed Dec 31 10:56:27.456053 2014] [:error] [pid 1138:tid 140421718034176] [remote 192.168.15.203:44679]     raise RuntimeError("populate() isn't reentrant")
[Wed Dec 31 10:56:27.456131 2014] [:error] [pid 1138:tid 140421718034176] [remote 192.168.15.203:44679] RuntimeError: populate() isn't reentrant
[Wed Dec 31 10:56:27.468056 2014] [:error] [pid 1138:tid 140421835532032] [remote 192.168.15.203:44679] mod_wsgi (pid=1138): Target WSGI script '/var/www/testsite/testsite/wsgi.py' cannot be loaded as Python module.
[Wed Dec 31 10:56:27.468091 2014] [:error] [pid 1138:tid 140421835532032] [remote 192.168.15.203:44679] mod_wsgi (pid=1138): Exception occurred processing WSGI script '/var/www/testsite/testsite/wsgi.py'.
[Wed Dec 31 10:56:27.468115 2014] [:error] [pid 1138:tid 140421835532032] [remote 192.168.15.203:44679] Traceback (most recent call last):
[Wed Dec 31 10:56:27.468141 2014] [:error] [pid 1138:tid 140421835532032] [remote 192.168.15.203:44679]   File "/var/www/testsite/testsite/wsgi.py", line 16, in <module>
[Wed Dec 31 10:56:27.468174 2014] [:error] [pid 1138:tid 140421835532032] [remote 192.168.15.203:44679]     application = get_wsgi_application()
[Wed Dec 31 10:56:27.468185 2014] [:error] [pid 1138:tid 140421835532032] [remote 192.168.15.203:44679]   File "/usr/local/lib/python2.7/dist-packages/django/core/wsgi.py", line 14, in get_wsgi_application
[Wed Dec 31 10:56:27.468207 2014] [:error] [pid 1138:tid 140421835532032] [remote 192.168.15.203:44679]     django.setup()
[Wed Dec 31 10:56:27.468220 2014] [:error] [pid 1138:tid 140421835532032] [remote 192.168.15.203:44679]   File "/usr/local/lib/python2.7/dist-packages/django/__init__.py", line 21, in setup
[Wed Dec 31 10:56:27.468237 2014] [:error] [pid 1138:tid 140421835532032] [remote 192.168.15.203:44679]     apps.populate(settings.INSTALLED_APPS)
[Wed Dec 31 10:56:27.468248 2014] [:error] [pid 1138:tid 140421835532032] [remote 192.168.15.203:44679]   File "/usr/local/lib/python2.7/dist-packages/django/apps/registry.py", line 78, in populate
[Wed Dec 31 10:56:27.468267 2014] [:error] [pid 1138:tid 140421835532032] [remote 192.168.15.203:44679]     raise RuntimeError("populate() isn't reentrant")
[Wed Dec 31 10:56:27.468302 2014] [:error] [pid 1138:tid 140421835532032] [remote 192.168.15.203:44679] RuntimeError: populate() isn't reentrant
[Wed Dec 31 11:01:21.939603 2014] [:error] [pid 1137:tid 140421827139328] [remote 192.168.15.203:44935] mod_wsgi (pid=1137): Target WSGI script '/var/www/testsite/testsite/wsgi.py' cannot be loaded as Python module.
[Wed Dec 31 11:01:21.939684 2014] [:error] [pid 1137:tid 140421827139328] [remote 192.168.15.203:44935] mod_wsgi (pid=1137): Exception occurred processing WSGI script '/var/www/testsite/testsite/wsgi.py'.
[Wed Dec 31 11:01:21.939730 2014] [:error] [pid 1137:tid 140421827139328] [remote 192.168.15.203:44935] Traceback (most recent call last):
[Wed Dec 31 11:01:21.939771 2014] [:error] [pid 1137:tid 140421827139328] [remote 192.168.15.203:44935]   File "/var/www/testsite/testsite/wsgi.py", line 16, in <module>
[Wed Dec 31 11:01:21.939823 2014] [:error] [pid 1137:tid 140421827139328] [remote 192.168.15.203:44935]     application = get_wsgi_application()
[Wed Dec 31 11:01:21.939835 2014] [:error] [pid 1137:tid 140421827139328] [remote 192.168.15.203:44935]   File "/usr/local/lib/python2.7/dist-packages/django/core/wsgi.py", line 14, in get_wsgi_application
[Wed Dec 31 11:01:21.939863 2014] [:error] [pid 1137:tid 140421827139328] [remote 192.168.15.203:44935]     django.setup()
[Wed Dec 31 11:01:21.939875 2014] [:error] [pid 1137:tid 140421827139328] [remote 192.168.15.203:44935]   File "/usr/local/lib/python2.7/dist-packages/django/__init__.py", line 21, in setup
[Wed Dec 31 11:01:21.939900 2014] [:error] [pid 1137:tid 140421827139328] [remote 192.168.15.203:44935]     apps.populate(settings.INSTALLED_APPS)
[Wed Dec 31 11:01:21.939911 2014] [:error] [pid 1137:tid 140421827139328] [remote 192.168.15.203:44935]   File "/usr/local/lib/python2.7/dist-packages/django/apps/registry.py", line 78, in populate
[Wed Dec 31 11:01:21.939936 2014] [:error] [pid 1137:tid 140421827139328] [remote 192.168.15.203:44935]     raise RuntimeError("populate() isn't reentrant")
[Wed Dec 31 11:01:21.939955 2014] [:error] [pid 1137:tid 140421827139328] [remote 192.168.15.203:44935] RuntimeError: populate() isn't reentrant
[Wed Dec 31 11:01:21.954762 2014] [:error] [pid 1138:tid 140421718034176] [remote 192.168.15.203:44679] mod_wsgi (pid=1138): Target WSGI script '/var/www/testsite/testsite/wsgi.py' cannot be loaded as Python module.
[Wed Dec 31 11:01:21.954820 2014] [:error] [pid 1138:tid 140421718034176] [remote 192.168.15.203:44679] mod_wsgi (pid=1138): Exception occurred processing WSGI script '/var/www/testsite/testsite/wsgi.py'.
[Wed Dec 31 11:01:21.954880 2014] [:error] [pid 1138:tid 140421718034176] [remote 192.168.15.203:44679] Traceback (most recent call last):
[Wed Dec 31 11:01:21.954923 2014] [:error] [pid 1138:tid 140421718034176] [remote 192.168.15.203:44679]   File "/var/www/testsite/testsite/wsgi.py", line 16, in <module>
[Wed Dec 31 11:01:21.955003 2014] [:error] [pid 1138:tid 140421718034176] [remote 192.168.15.203:44679]     application = get_wsgi_application()
[Wed Dec 31 11:01:21.955016 2014] [:error] [pid 1138:tid 140421718034176] [remote 192.168.15.203:44679]   File "/usr/local/lib/python2.7/dist-packages/django/core/wsgi.py", line 14, in get_wsgi_application
[Wed Dec 31 11:01:21.955044 2014] [:error] [pid 1138:tid 140421718034176] [remote 192.168.15.203:44679]     django.setup()
[Wed Dec 31 11:01:21.955056 2014] [:error] [pid 1138:tid 140421718034176] [remote 192.168.15.203:44679]   File "/usr/local/lib/python2.7/dist-packages/django/__init__.py", line 21, in setup
[Wed Dec 31 11:01:21.955080 2014] [:error] [pid 1138:tid 140421718034176] [remote 192.168.15.203:44679]     apps.populate(settings.INSTALLED_APPS)
[Wed Dec 31 11:01:21.955092 2014] [:error] [pid 1138:tid 140421718034176] [remote 192.168.15.203:44679]   File "/usr/local/lib/python2.7/dist-packages/django/apps/registry.py", line 78, in populate
[Wed Dec 31 11:01:21.955117 2014] [:error] [pid 1138:tid 140421718034176] [remote 192.168.15.203:44679]     raise RuntimeError("populate() isn't reentrant")
[Wed Dec 31 11:01:21.955151 2014] [:error] [pid 1138:tid 140421718034176] [remote 192.168.15.203:44679] RuntimeError: populate() isn't reentrant
[Wed Dec 31 11:01:22.544090 2014] [:error] [pid 1137:tid 140421718034176] [remote 192.168.15.203:44935] mod_wsgi (pid=1137): Target WSGI script '/var/www/testsite/testsite/wsgi.py' cannot be loaded as Python module.
[Wed Dec 31 11:01:22.544122 2014] [:error] [pid 1137:tid 140421718034176] [remote 192.168.15.203:44935] mod_wsgi (pid=1137): Exception occurred processing WSGI script '/var/www/testsite/testsite/wsgi.py'.
[Wed Dec 31 11:01:22.544142 2014] [:error] [pid 1137:tid 140421718034176] [remote 192.168.15.203:44935] Traceback (most recent call last):
[Wed Dec 31 11:01:22.544163 2014] [:error] [pid 1137:tid 140421718034176] [remote 192.168.15.203:44935]   File "/var/www/testsite/testsite/wsgi.py", line 16, in <module>
[Wed Dec 31 11:01:22.544195 2014] [:error] [pid 1137:tid 140421718034176] [remote 192.168.15.203:44935]     application = get_wsgi_application()
[Wed Dec 31 11:01:22.544206 2014] [:error] [pid 1137:tid 140421718034176] [remote 192.168.15.203:44935]   File "/usr/local/lib/python2.7/dist-packages/django/core/wsgi.py", line 14, in get_wsgi_application
[Wed Dec 31 11:01:22.544227 2014] [:error] [pid 1137:tid 140421718034176] [remote 192.168.15.203:44935]     django.setup()
[Wed Dec 31 11:01:22.544233 2014] [:error] [pid 1137:tid 140421718034176] [remote 192.168.15.203:44935]   File "/usr/local/lib/python2.7/dist-packages/django/__init__.py", line 21, in setup
[Wed Dec 31 11:01:22.544233 2014] [:error] [pid 1137:tid 140421718034176] [remote 192.168.15.203:44935]     apps.populate(settings.INSTALLED_APPS)
[Wed Dec 31 11:01:22.544233 2014] [:error] [pid 1137:tid 140421718034176] [remote 192.168.15.203:44935]   File "/usr/local/lib/python2.7/dist-packages/django/apps/registry.py", line 78, in populate
[Wed Dec 31 11:01:22.544233 2014] [:error] [pid 1137:tid 140421718034176] [remote 192.168.15.203:44935]     raise RuntimeError("populate() isn't reentrant")
[Wed Dec 31 11:01:22.544233 2014] [:error] [pid 1137:tid 140421718034176] [remote 192.168.15.203:44935] RuntimeError: populate() isn't reentrant
[Wed Dec 31 11:01:22.557689 2014] [:error] [pid 1138:tid 140421835532032] [remote 192.168.15.203:44679] mod_wsgi (pid=1138): Target WSGI script '/var/www/testsite/testsite/wsgi.py' cannot be loaded as Python module.
[Wed Dec 31 11:01:22.557752 2014] [:error] [pid 1138:tid 140421835532032] [remote 192.168.15.203:44679] mod_wsgi (pid=1138): Exception occurred processing WSGI script '/var/www/testsite/testsite/wsgi.py'.
[Wed Dec 31 11:01:22.557778 2014] [:error] [pid 1138:tid 140421835532032] [remote 192.168.15.203:44679] Traceback (most recent call last):
[Wed Dec 31 11:01:22.557818 2014] [:error] [pid 1138:tid 140421835532032] [remote 192.168.15.203:44679]   File "/var/www/testsite/testsite/wsgi.py", line 16, in <module>
[Wed Dec 31 11:01:22.557869 2014] [:error] [pid 1138:tid 140421835532032] [remote 192.168.15.203:44679]     application = get_wsgi_application()
[Wed Dec 31 11:01:22.557881 2014] [:error] [pid 1138:tid 140421835532032] [remote 192.168.15.203:44679]   File "/usr/local/lib/python2.7/dist-packages/django/core/wsgi.py", line 14, in get_wsgi_application
[Wed Dec 31 11:01:22.557905 2014] [:error] [pid 1138:tid 140421835532032] [remote 192.168.15.203:44679]     django.setup()
[Wed Dec 31 11:01:22.557916 2014] [:error] [pid 1138:tid 140421835532032] [remote 192.168.15.203:44679]   File "/usr/local/lib/python2.7/dist-packages/django/__init__.py", line 21, in setup
[Wed Dec 31 11:01:22.557934 2014] [:error] [pid 1138:tid 140421835532032] [remote 192.168.15.203:44679]     apps.populate(settings.INSTALLED_APPS)
[Wed Dec 31 11:01:22.557945 2014] [:error] [pid 1138:tid 140421835532032] [remote 192.168.15.203:44679]   File "/usr/local/lib/python2.7/dist-packages/django/apps/registry.py", line 78, in populate
[Wed Dec 31 11:01:22.557963 2014] [:error] [pid 1138:tid 140421835532032] [remote 192.168.15.203:44679]     raise RuntimeError("populate() isn't reentrant")
[Wed Dec 31 11:01:22.558004 2014] [:error] [pid 1138:tid 140421835532032] [remote 192.168.15.203:44679] RuntimeError: populate() isn't reentrant
[Wed Dec 31 11:02:06.018764 2014] [:error] [pid 1137:tid 140421827139328] [remote 192.168.15.203:44935] mod_wsgi (pid=1137): Target WSGI script '/var/www/testsite/testsite/wsgi.py' cannot be loaded as Python module.
[Wed Dec 31 11:02:06.018834 2014] [:error] [pid 1137:tid 140421827139328] [remote 192.168.15.203:44935] mod_wsgi (pid=1137): Exception occurred processing WSGI script '/var/www/testsite/testsite/wsgi.py'.
[Wed Dec 31 11:02:06.018874 2014] [:error] [pid 1137:tid 140421827139328] [remote 192.168.15.203:44935] Traceback (most recent call last):
[Wed Dec 31 11:02:06.018916 2014] [:error] [pid 1137:tid 140421827139328] [remote 192.168.15.203:44935]   File "/var/www/testsite/testsite/wsgi.py", line 16, in <module>
[Wed Dec 31 11:02:06.019018 2014] [:error] [pid 1137:tid 140421827139328] [remote 192.168.15.203:44935]     application = get_wsgi_application()
[Wed Dec 31 11:02:06.019031 2014] [:error] [pid 1137:tid 140421827139328] [remote 192.168.15.203:44935]   File "/usr/local/lib/python2.7/dist-packages/django/core/wsgi.py", line 14, in get_wsgi_application
[Wed Dec 31 11:02:06.019061 2014] [:error] [pid 1137:tid 140421827139328] [remote 192.168.15.203:44935]     django.setup()
[Wed Dec 31 11:02:06.019078 2014] [:error] [pid 1137:tid 140421827139328] [remote 192.168.15.203:44935]   File "/usr/local/lib/python2.7/dist-packages/django/__init__.py", line 21, in setup
[Wed Dec 31 11:02:06.019102 2014] [:error] [pid 1137:tid 140421827139328] [remote 192.168.15.203:44935]     apps.populate(settings.INSTALLED_APPS)
[Wed Dec 31 11:02:06.019114 2014] [:error] [pid 1137:tid 140421827139328] [remote 192.168.15.203:44935]   File "/usr/local/lib/python2.7/dist-packages/django/apps/registry.py", line 78, in populate
[Wed Dec 31 11:02:06.019145 2014] [:error] [pid 1137:tid 140421827139328] [remote 192.168.15.203:44935]     raise RuntimeError("populate() isn't reentrant")
[Wed Dec 31 11:02:06.019168 2014] [:error] [pid 1137:tid 140421827139328] [remote 192.168.15.203:44935] RuntimeError: populate() isn't reentrant
[Wed Dec 31 11:02:06.048402 2014] [:error] [pid 1138:tid 140421718034176] [remote 192.168.15.203:44679] mod_wsgi (pid=1138): Target WSGI script '/var/www/testsite/testsite/wsgi.py' cannot be loaded as Python module.
[Wed Dec 31 11:02:06.048482 2014] [:error] [pid 1138:tid 140421718034176] [remote 192.168.15.203:44679] mod_wsgi (pid=1138): Exception occurred processing WSGI script '/var/www/testsite/testsite/wsgi.py'.
[Wed Dec 31 11:02:06.048532 2014] [:error] [pid 1138:tid 140421718034176] [remote 192.168.15.203:44679] Traceback (most recent call last):
[Wed Dec 31 11:02:06.048576 2014] [:error] [pid 1138:tid 140421718034176] [remote 192.168.15.203:44679]   File "/var/www/testsite/testsite/wsgi.py", line 16, in <module>
[Wed Dec 31 11:02:06.048654 2014] [:error] [pid 1138:tid 140421718034176] [remote 192.168.15.203:44679]     application = get_wsgi_application()
[Wed Dec 31 11:02:06.048668 2014] [:error] [pid 1138:tid 140421718034176] [remote 192.168.15.203:44679]   File "/usr/local/lib/python2.7/dist-packages/django/core/wsgi.py", line 14, in get_wsgi_application
[Wed Dec 31 11:02:06.048699 2014] [:error] [pid 1138:tid 140421718034176] [remote 192.168.15.203:44679]     django.setup()
[Wed Dec 31 11:02:06.048712 2014] [:error] [pid 1138:tid 140421718034176] [remote 192.168.15.203:44679]   File "/usr/local/lib/python2.7/dist-packages/django/__init__.py", line 21, in setup
[Wed Dec 31 11:02:06.048737 2014] [:error] [pid 1138:tid 140421718034176] [remote 192.168.15.203:44679]     apps.populate(settings.INSTALLED_APPS)
[Wed Dec 31 11:02:06.048750 2014] [:error] [pid 1138:tid 140421718034176] [remote 192.168.15.203:44679]   File "/usr/local/lib/python2.7/dist-packages/django/apps/registry.py", line 78, in populate
[Wed Dec 31 11:02:06.048776 2014] [:error] [pid 1138:tid 140421718034176] [remote 192.168.15.203:44679]     raise RuntimeError("populate() isn't reentrant")
[Wed Dec 31 11:02:06.048825 2014] [:error] [pid 1138:tid 140421718034176] [remote 192.168.15.203:44679] RuntimeError: populate() isn't reentrant
